File: G03832.csv
[Measurement conditions]
Sample identification,Ag-EA 5layers on glass
Comment - 1,"Configuration=Programmable xy with programmable z platforms, Owner=User, Creation date=02/07/2021 13:22:25"
Comment - 2,"Goniometer=Theta/Theta; Minimum step size 2Theta:0.0001; Minimum step size Omega:0.0001"
Comment - 3,"Sample stage=Programmable xy-platform with programmable z-adjustment; Minimum step size X:0.01; Minimum step size Y:0.01; Minimum step size Z:0.001"
Comment - 4,"Diffractometer system=EMPYREAN"
Comment - 5,"Measurement program=C:\PANalytical\Data Collector\Programs\Knapp Group (CK)\Songming Liu\20-80°, 0.05° step, 0.5s-step.xrdmp, Created identifier={D6D0720B-9417-4404-86A5-80CEFF14CAE1}, Created by=User, Id=WL:EMPYREANGI:User, Creation date=20/06/2024 10:10:34"
Anode material,Cu
K-Alpha1 wavelength,1.5405980
K-Alpha2 wavelength,1.5444260
Ratio K-Alpha2/K-Alpha1,0.500
Divergence slit,Fixed,0.76mm
Monochromator used,NO
Generator voltage, 40
Tube current, 40
File date and time,20/Jun/2024 10:41
Unit cell,
h k l, 0 0 0
Scan axis,2Theta
Scan range,20.00000,80.00000
Scan step size,0.0500000
No. of points, 1200
Scan type,CONTINUOUS
Omega,1.0000
X,-2.61
Y,2.01
Z,20.318
Time per step,0.50
[Scan points]
Angle, TimePerStep, Intensity, ESD
20.02500, 0.50, 101.0, 10.0499
20.07500, 0.50, 120.0, 10.9545
20.12500, 0.50, 96.0, 9.7980
20.17500, 0.50, 98.0, 9.8995
20.22500, 0.50, 108.0, 10.3923
20.27500, 0.50, 106.0, 10.2956
20.32500, 0.50, 115.0, 10.7238
20.37500, 0.50, 114.0, 10.6771
20.42500, 0.50, 118.0, 10.8628
20.47500, 0.50, 106.0, 10.2956
20.52500, 0.50, 106.0, 10.2956
20.57500, 0.50, 124.0, 11.1355
20.62500, 0.50, 100.0, 10.0000
20.67500, 0.50, 108.0, 10.3923
20.72500, 0.50, 118.0, 10.8628
20.77500, 0.50, 101.0, 10.0499
20.82500, 0.50, 108.0, 10.3923
20.87500, 0.50, 109.0, 10.4403
20.92500, 0.50, 122.0, 11.0454
20.97500, 0.50, 90.0, 9.4868
21.02500, 0.50, 106.0, 10.2956
21.07500, 0.50, 110.0, 10.4881
21.12500, 0.50, 109.0, 10.4403
21.17500, 0.50, 108.0, 10.3923
21.22500, 0.50, 110.0, 10.4881
21.27500, 0.50, 120.0, 10.9545
21.32500, 0.50, 114.0, 10.6771
21.37500, 0.50, 95.0, 9.7468
21.42500, 0.50, 79.0, 8.8882
21.47500, 0.50, 111.0, 10.5357
21.52500, 0.50, 115.0, 10.7238
21.57500, 0.50, 104.0, 10.1980
21.62500, 0.50, 98.0, 9.8995
21.67500, 0.50, 100.0, 10.0000
21.72500, 0.50, 92.0, 9.5917
21.77500, 0.50, 116.0, 10.7703
21.82500, 0.50, 80.0, 8.9443
21.87500, 0.50, 119.0, 10.9087
21.92500, 0.50, 116.0, 10.7703
21.97500, 0.50, 113.0, 10.6301
22.02500, 0.50, 105.0, 10.2470
22.07500, 0.50, 114.0, 10.6771
22.12500, 0.50, 116.0, 10.7703
22.17500, 0.50, 85.0, 9.2195
22.22500, 0.50, 111.0, 10.5357
22.27500, 0.50, 89.0, 9.4340
22.32500, 0.50, 109.0, 10.4403
22.37500, 0.50, 99.0, 9.9499
22.42500, 0.50, 104.0, 10.1980
22.47500, 0.50, 124.0, 11.1355
22.52500, 0.50, 116.0, 10.7703
22.57500, 0.50, 84.0, 9.1652
22.62500, 0.50, 96.0, 9.7980
22.67500, 0.50, 102.0, 10.0995
22.72500, 0.50, 92.0, 9.5917
22.77500, 0.50, 109.0, 10.4403
22.82500, 0.50, 83.0, 9.1104
22.87500, 0.50, 104.0, 10.1980
22.92500, 0.50, 106.0, 10.2956
22.97500, 0.50, 101.0, 10.0499
23.02500, 0.50, 106.0, 10.2956
23.07500, 0.50, 108.0, 10.3923
23.12500, 0.50, 108.0, 10.3923
23.17500, 0.50, 103.0, 10.1489
23.22500, 0.50, 120.0, 10.9545
23.27500, 0.50, 85.0, 9.2195
23.32500, 0.50, 106.0, 10.2956
23.37500, 0.50, 104.0, 10.1980
23.42500, 0.50, 93.0, 9.6437
23.47500, 0.50, 125.0, 11.1803
23.52500, 0.50, 112.0, 10.5830
23.57500, 0.50, 93.0, 9.6437
23.62500, 0.50, 97.0, 9.8489
23.67500, 0.50, 94.0, 9.6954
23.72500, 0.50, 91.0, 9.5394
23.77500, 0.50, 104.0, 10.1980
23.82500, 0.50, 92.0, 9.5917
23.87500, 0.50, 86.0, 9.2736
23.92500, 0.50, 92.0, 9.5917
23.97500, 0.50, 96.0, 9.7980
24.02500, 0.50, 92.0, 9.5917
24.07500, 0.50, 81.0, 9.0000
24.12500, 0.50, 107.0, 10.3441
24.17500, 0.50, 77.0, 8.7750
24.22500, 0.50, 103.0, 10.1489
24.27500, 0.50, 107.0, 10.3441
24.32500, 0.50, 84.0, 9.1652
24.37500, 0.50, 92.0, 9.5917
24.42500, 0.50, 71.0, 8.4261
24.47500, 0.50, 105.0, 10.2470
24.52500, 0.50, 76.0, 8.7178
24.57500, 0.50, 98.0, 9.8995
24.62500, 0.50, 82.0, 9.0554
24.67500, 0.50, 95.0, 9.7468
24.72500, 0.50, 69.0, 8.3066
24.77500, 0.50, 86.0, 9.2736
24.82500, 0.50, 66.0, 8.1240
24.87500, 0.50, 87.0, 9.3274
24.92500, 0.50, 73.0, 8.5440
24.97500, 0.50, 84.0, 9.1652
25.02500, 0.50, 88.0, 9.3808
25.07500, 0.50, 84.0, 9.1652
25.12500, 0.50, 85.0, 9.2195
25.17500, 0.50, 85.0, 9.2195
25.22500, 0.50, 91.0, 9.5394
25.27500, 0.50, 79.0, 8.8882
25.32500, 0.50, 72.0, 8.4853
25.37500, 0.50, 79.0, 8.8882
25.42500, 0.50, 75.0, 8.6603
25.47500, 0.50, 79.0, 8.8882
25.52500, 0.50, 72.0, 8.4853
25.57500, 0.50, 86.0, 9.2736
25.62500, 0.50, 100.0, 10.0000
25.67500, 0.50, 74.0, 8.6023
25.72500, 0.50, 78.0, 8.8318
25.77500, 0.50, 83.0, 9.1104
25.82500, 0.50, 85.0, 9.2195
25.87500, 0.50, 81.0, 9.0000
25.92500, 0.50, 65.0, 8.0623
25.97500, 0.50, 80.0, 8.9443
26.02500, 0.50, 76.0, 8.7178
26.07500, 0.50, 70.0, 8.3666
26.12500, 0.50, 95.0, 9.7468
26.17500, 0.50, 73.0, 8.5440
26.22500, 0.50, 79.0, 8.8882
26.27500, 0.50, 74.0, 8.6023
26.32500, 0.50, 68.0, 8.2462
26.37500, 0.50, 65.0, 8.0623
26.42500, 0.50, 64.0, 8.0000
26.47500, 0.50, 59.0, 7.6811
26.52500, 0.50, 60.0, 7.7460
26.57500, 0.50, 58.0, 7.6158
26.62500, 0.50, 62.0, 7.8740
26.67500, 0.50, 65.0, 8.0623
26.72500, 0.50, 61.0, 7.8102
26.77500, 0.50, 64.0, 8.0000
26.82500, 0.50, 67.0, 8.1854
26.87500, 0.50, 58.0, 7.6158
26.92500, 0.50, 75.0, 8.6603
26.97500, 0.50, 72.0, 8.4853
27.02500, 0.50, 56.0, 7.4833
27.07500, 0.50, 64.0, 8.0000
27.12500, 0.50, 58.0, 7.6158
27.17500, 0.50, 55.0, 7.4162
27.22500, 0.50, 59.0, 7.6811
27.27500, 0.50, 82.0, 9.0554
27.32500, 0.50, 59.0, 7.6811
27.37500, 0.50, 69.0, 8.3066
27.42500, 0.50, 70.0, 8.3666
27.47500, 0.50, 68.0, 8.2462
27.52500, 0.50, 48.0, 6.9282
27.57500, 0.50, 83.0, 9.1104
27.62500, 0.50, 69.0, 8.3066
27.67500, 0.50, 73.0, 8.5440
27.72500, 0.50, 78.0, 8.8318
27.77500, 0.50, 48.0, 6.9282
27.82500, 0.50, 63.0, 7.9373
27.87500, 0.50, 69.0, 8.3066
27.92500, 0.50, 66.0, 8.1240
27.97500, 0.50, 83.0, 9.1104
28.02500, 0.50, 48.0, 6.9282
28.07500, 0.50, 64.0, 8.0000
28.12500, 0.50, 56.0, 7.4833
28.17500, 0.50, 61.0, 7.8102
28.22500, 0.50, 56.0, 7.4833
28.27500, 0.50, 68.0, 8.2462
28.32500, 0.50, 63.0, 7.9373
28.37500, 0.50, 66.0, 8.1240
28.42500, 0.50, 63.0, 7.9373
28.47500, 0.50, 38.0, 6.1644
28.52500, 0.50, 57.0, 7.5498
28.57500, 0.50, 41.0, 6.4031
28.62500, 0.50, 60.0, 7.7460
28.67500, 0.50, 51.0, 7.1414
28.72500, 0.50, 64.0, 8.0000
28.77500, 0.50, 66.0, 8.1240
28.82500, 0.50, 57.0, 7.5498
28.87500, 0.50, 58.0, 7.6158
28.92500, 0.50, 52.0, 7.2111
28.97500, 0.50, 53.0, 7.2801
29.02500, 0.50, 46.0, 6.7823
29.07500, 0.50, 56.0, 7.4833
29.12500, 0.50, 48.0, 6.9282
29.17500, 0.50, 69.0, 8.3066
29.22500, 0.50, 50.0, 7.0711
29.27500, 0.50, 55.0, 7.4162
29.32500, 0.50, 53.0, 7.2801
29.37500, 0.50, 48.0, 6.9282
29.42500, 0.50, 46.0, 6.7823
29.47500, 0.50, 45.0, 6.7082
29.52500, 0.50, 45.0, 6.7082
29.57500, 0.50, 45.0, 6.7082
29.62500, 0.50, 44.0, 6.6332
29.67500, 0.50, 31.0, 5.5678
29.72500, 0.50, 49.0, 7.0000
29.77500, 0.50, 42.0, 6.4807
29.82500, 0.50, 47.0, 6.8557
29.87500, 0.50, 52.0, 7.2111
29.92500, 0.50, 36.0, 6.0000
29.97500, 0.50, 47.0, 6.8557
30.02500, 0.50, 32.0, 5.6569
30.07500, 0.50, 54.0, 7.3485
30.12500, 0.50, 41.0, 6.4031
30.17500, 0.50, 45.0, 6.7082
30.22500, 0.50, 40.0, 6.3246
30.27500, 0.50, 44.0, 6.6332
30.32500, 0.50, 50.0, 7.0711
30.37500, 0.50, 57.0, 7.5498
30.42500, 0.50, 48.0, 6.9282
30.47500, 0.50, 39.0, 6.2450
30.52500, 0.50, 33.0, 5.7446
30.57500, 0.50, 49.0, 7.0000
30.62500, 0.50, 42.0, 6.4807
30.67500, 0.50, 53.0, 7.2801
30.72500, 0.50, 43.0, 6.5574
30.77500, 0.50, 52.0, 7.2111
30.82500, 0.50, 49.0, 7.0000
30.87500, 0.50, 54.0, 7.3485
30.92500, 0.50, 43.0, 6.5574
30.97500, 0.50, 51.0, 7.1414
31.02500, 0.50, 34.0, 5.8310
31.07500, 0.50, 40.0, 6.3246
31.12500, 0.50, 38.0, 6.1644
31.17500, 0.50, 41.0, 6.4031
31.22500, 0.50, 50.0, 7.0711
31.27500, 0.50, 37.0, 6.0828
31.32500, 0.50, 43.0, 6.5574
31.37500, 0.50, 40.0, 6.3246
31.42500, 0.50, 48.0, 6.9282
31.47500, 0.50, 31.0, 5.5678
31.52500, 0.50, 40.0, 6.3246
31.57500, 0.50, 37.0, 6.0828
31.62500, 0.50, 32.0, 5.6569
31.67500, 0.50, 29.0, 5.3852
31.72500, 0.50, 36.0, 6.0000
31.77500, 0.50, 36.0, 6.0000
31.82500, 0.50, 38.0, 6.1644
31.87500, 0.50, 38.0, 6.1644
31.92500, 0.50, 29.0, 5.3852
31.97500, 0.50, 40.0, 6.3246
32.02500, 0.50, 30.0, 5.4772
32.07500, 0.50, 34.0, 5.8310
32.12500, 0.50, 44.0, 6.6332
32.17500, 0.50, 47.0, 6.8557
32.22500, 0.50, 37.0, 6.0828
32.27500, 0.50, 47.0, 6.8557
32.32500, 0.50, 46.0, 6.7823
32.37500, 0.50, 34.0, 5.8310
32.42500, 0.50, 28.0, 5.2915
32.47500, 0.50, 36.0, 6.0000
32.52500, 0.50, 36.0, 6.0000
32.57500, 0.50, 35.0, 5.9161
32.62500, 0.50, 32.0, 5.6569
32.67500, 0.50, 30.0, 5.4772
32.72500, 0.50, 37.0, 6.0828
32.77500, 0.50, 35.0, 5.9161
32.82500, 0.50, 36.0, 6.0000
32.87500, 0.50, 42.0, 6.4807
32.92500, 0.50, 39.0, 6.2450
32.97500, 0.50, 36.0, 6.0000
33.02500, 0.50, 29.0, 5.3852
33.07500, 0.50, 37.0, 6.0828
33.12500, 0.50, 30.0, 5.4772
33.17500, 0.50, 38.0, 6.1644
33.22500, 0.50, 34.0, 5.8310
33.27500, 0.50, 33.0, 5.7446
33.32500, 0.50, 31.0, 5.5678
33.37500, 0.50, 34.0, 5.8310
33.42500, 0.50, 29.0, 5.3852
33.47500, 0.50, 36.0, 6.0000
33.52500, 0.50, 39.0, 6.2450
33.57500, 0.50, 33.0, 5.7446
33.62500, 0.50, 34.0, 5.8310
33.67500, 0.50, 26.0, 5.0990
33.72500, 0.50, 26.0, 5.0990
33.77500, 0.50, 26.0, 5.0990
33.82500, 0.50, 29.0, 5.3852
33.87500, 0.50, 27.0, 5.1962
33.92500, 0.50, 32.0, 5.6569
33.97500, 0.50, 30.0, 5.4772
34.02500, 0.50, 35.0, 5.9161
34.07500, 0.50, 37.0, 6.0828
34.12500, 0.50, 41.0, 6.4031
34.17500, 0.50, 40.0, 6.3246
34.22500, 0.50, 35.0, 5.9161
34.27500, 0.50, 34.0, 5.8310
34.32500, 0.50, 32.0, 5.6569
34.37500, 0.50, 32.0, 5.6569
34.42500, 0.50, 37.0, 6.0828
34.47500, 0.50, 28.0, 5.2915
34.52500, 0.50, 28.0, 5.2915
34.57500, 0.50, 34.0, 5.8310
34.62500, 0.50, 29.0, 5.3852
34.67500, 0.50, 31.0, 5.5678
34.72500, 0.50, 22.0, 4.6904
34.77500, 0.50, 33.0, 5.7446
34.82500, 0.50, 26.0, 5.0990
34.87500, 0.50, 34.0, 5.8310
34.92500, 0.50, 30.0, 5.4772
34.97500, 0.50, 28.0, 5.2915
35.02500, 0.50, 23.0, 4.7958
35.07500, 0.50, 23.0, 4.7958
35.12500, 0.50, 28.0, 5.2915
35.17500, 0.50, 32.0, 5.6569
35.22500, 0.50, 32.0, 5.6569
35.27500, 0.50, 32.0, 5.6569
35.32500, 0.50, 33.0, 5.7446
35.37500, 0.50, 25.0, 5.0000
35.42500, 0.50, 30.0, 5.4772
35.47500, 0.50, 26.0, 5.0990
35.52500, 0.50, 33.0, 5.7446
35.57500, 0.50, 34.0, 5.8310
35.62500, 0.50, 39.0, 6.2450
35.67500, 0.50, 24.0, 4.8990
35.72500, 0.50, 33.0, 5.7446
35.77500, 0.50, 25.0, 5.0000
35.82500, 0.50, 32.0, 5.6569
35.87500, 0.50, 22.0, 4.6904
35.92500, 0.50, 34.0, 5.8310
35.97500, 0.50, 32.0, 5.6569
36.02500, 0.50, 49.0, 7.0000
36.07500, 0.50, 35.0, 5.9161
36.12500, 0.50, 39.0, 6.2450
36.17500, 0.50, 37.0, 6.0828
36.22500, 0.50, 30.0, 5.4772
36.27500, 0.50, 25.0, 5.0000
36.32500, 0.50, 30.0, 5.4772
36.37500, 0.50, 31.0, 5.5678
36.42500, 0.50, 26.0, 5.0990
36.47500, 0.50, 29.0, 5.3852
36.52500, 0.50, 34.0, 5.8310
36.57500, 0.50, 39.0, 6.2450
36.62500, 0.50, 40.0, 6.3246
36.67500, 0.50, 31.0, 5.5678
36.72500, 0.50, 34.0, 5.8310
36.77500, 0.50, 22.0, 4.6904
36.82500, 0.50, 28.0, 5.2915
36.87500, 0.50, 29.0, 5.3852
36.92500, 0.50, 32.0, 5.6569
36.97500, 0.50, 40.0, 6.3246
37.02500, 0.50, 49.0, 7.0000
37.07500, 0.50, 34.0, 5.8310
37.12500, 0.50, 36.0, 6.0000
37.17500, 0.50, 36.0, 6.0000
37.22500, 0.50, 42.0, 6.4807
37.27500, 0.50, 44.0, 6.6332
37.32500, 0.50, 41.0, 6.4031
37.37500, 0.50, 41.0, 6.4031
37.42500, 0.50, 63.0, 7.9373
37.47500, 0.50, 74.0, 8.6023
37.52500, 0.50, 73.0, 8.5440
37.57500, 0.50, 77.0, 8.7750
37.62500, 0.50, 83.0, 9.1104
37.67500, 0.50, 104.0, 10.1980
37.72500, 0.50, 114.0, 10.6771
37.77500, 0.50, 200.0, 14.1421
37.82500, 0.50, 298.0, 17.2627
37.87500, 0.50, 419.0, 20.4695
37.92500, 0.50, 617.0, 24.8395
37.97500, 0.50, 827.0, 28.7576
38.02500, 0.50, 1208.0, 34.7563
38.07500, 0.50, 1443.0, 37.9868
38.12500, 0.50, 1399.0, 37.4032
38.17500, 0.50, 1050.0, 32.4037
38.22500, 0.50, 776.0, 27.8568
38.27500, 0.50, 436.0, 20.8806
38.32500, 0.50, 258.0, 16.0624
38.37500, 0.50, 174.0, 13.1909
38.42500, 0.50, 118.0, 10.8628
38.47500, 0.50, 112.0, 10.5830
38.52500, 0.50, 82.0, 9.0554
38.57500, 0.50, 66.0, 8.1240
38.62500, 0.50, 65.0, 8.0623
38.67500, 0.50, 60.0, 7.7460
38.72500, 0.50, 68.0, 8.2462
38.77500, 0.50, 46.0, 6.7823
38.82500, 0.50, 42.0, 6.4807
38.87500, 0.50, 39.0, 6.2450
38.92500, 0.50, 48.0, 6.9282
38.97500, 0.50, 46.0, 6.7823
39.02500, 0.50, 26.0, 5.0990
39.07500, 0.50, 30.0, 5.4772
39.12500, 0.50, 30.0, 5.4772
39.17500, 0.50, 27.0, 5.1962
39.22500, 0.50, 33.0, 5.7446
39.27500, 0.50, 28.0, 5.2915
39.32500, 0.50, 30.0, 5.4772
39.37500, 0.50, 34.0, 5.8310
39.42500, 0.50, 32.0, 5.6569
39.47500, 0.50, 27.0, 5.1962
39.52500, 0.50, 15.0, 3.8730
39.57500, 0.50, 29.0, 5.3852
39.62500, 0.50, 28.0, 5.2915
39.67500, 0.50, 33.0, 5.7446
39.72500, 0.50, 33.0, 5.7446
39.77500, 0.50, 28.0, 5.2915
39.82500, 0.50, 21.0, 4.5826
39.87500, 0.50, 24.0, 4.8990
39.92500, 0.50, 46.0, 6.7823
39.97500, 0.50, 27.0, 5.1962
40.02500, 0.50, 24.0, 4.8990
40.07500, 0.50, 25.0, 5.0000
40.12500, 0.50, 26.0, 5.0990
40.17500, 0.50, 21.0, 4.5826
40.22500, 0.50, 29.0, 5.3852
40.27500, 0.50, 23.0, 4.7958
40.32500, 0.50, 23.0, 4.7958
40.37500, 0.50, 26.0, 5.0990
40.42500, 0.50, 23.0, 4.7958
40.47500, 0.50, 20.0, 4.4721
40.52500, 0.50, 19.0, 4.3589
40.57500, 0.50, 19.0, 4.3589
40.62500, 0.50, 21.0, 4.5826
40.67500, 0.50, 21.0, 4.5826
40.72500, 0.50, 19.0, 4.3589
40.77500, 0.50, 28.0, 5.2915
40.82500, 0.50, 17.0, 4.1231
40.87500, 0.50, 19.0, 4.3589
40.92500, 0.50, 15.0, 3.8730
40.97500, 0.50, 22.0, 4.6904
41.02500, 0.50, 21.0, 4.5826
41.07500, 0.50, 29.0, 5.3852
41.12500, 0.50, 31.0, 5.5678
41.17500, 0.50, 22.0, 4.6904
41.22500, 0.50, 23.0, 4.7958
41.27500, 0.50, 14.0, 3.7417
41.32500, 0.50, 17.0, 4.1231
41.37500, 0.50, 24.0, 4.8990
41.42500, 0.50, 16.0, 4.0000
41.47500, 0.50, 21.0, 4.5826
41.52500, 0.50, 15.0, 3.8730
41.57500, 0.50, 16.0, 4.0000
41.62500, 0.50, 19.0, 4.3589
41.67500, 0.50, 26.0, 5.0990
41.72500, 0.50, 19.0, 4.3589
41.77500, 0.50, 20.0, 4.4721
41.82500, 0.50, 25.0, 5.0000
41.87500, 0.50, 17.0, 4.1231
41.92500, 0.50, 24.0, 4.8990
41.97500, 0.50, 22.0, 4.6904
42.02500, 0.50, 16.0, 4.0000
42.07500, 0.50, 25.0, 5.0000
42.12500, 0.50, 20.0, 4.4721
42.17500, 0.50, 24.0, 4.8990
42.22500, 0.50, 21.0, 4.5826
42.27500, 0.50, 18.0, 4.2426
42.32500, 0.50, 16.0, 4.0000
42.37500, 0.50, 18.0, 4.2426
42.42500, 0.50, 22.0, 4.6904
42.47500, 0.50, 26.0, 5.0990
42.52500, 0.50, 13.0, 3.6056
42.57500, 0.50, 24.0, 4.8990
42.62500, 0.50, 21.0, 4.5826
42.67500, 0.50, 13.0, 3.6056
42.72500, 0.50, 26.0, 5.0990
42.77500, 0.50, 19.0, 4.3589
42.82500, 0.50, 25.0, 5.0000
42.87500, 0.50, 14.0, 3.7417
42.92500, 0.50, 21.0, 4.5826
42.97500, 0.50, 25.0, 5.0000
43.02500, 0.50, 21.0, 4.5826
43.07500, 0.50, 24.0, 4.8990
43.12500, 0.50, 31.0, 5.5678
43.17500, 0.50, 35.0, 5.9161
43.22500, 0.50, 23.0, 4.7958
43.27500, 0.50, 19.0, 4.3589
43.32500, 0.50, 24.0, 4.8990
43.37500, 0.50, 30.0, 5.4772
43.42500, 0.50, 31.0, 5.5678
43.47500, 0.50, 33.0, 5.7446
43.52500, 0.50, 26.0, 5.0990
43.57500, 0.50, 31.0, 5.5678
43.62500, 0.50, 40.0, 6.3246
43.67500, 0.50, 27.0, 5.1962
43.72500, 0.50, 43.0, 6.5574
43.77500, 0.50, 42.0, 6.4807
43.82500, 0.50, 61.0, 7.8102
43.87500, 0.50, 69.0, 8.3066
43.92500, 0.50, 99.0, 9.9499
43.97500, 0.50, 117.0, 10.8167
44.02500, 0.50, 143.0, 11.9583
44.07500, 0.50, 212.0, 14.5602
44.12500, 0.50, 302.0, 17.3781
44.17500, 0.50, 382.0, 19.5448
44.22500, 0.50, 495.0, 22.2486
44.27500, 0.50, 468.0, 21.6333
44.32500, 0.50, 418.0, 20.4450
44.37500, 0.50, 387.0, 19.6723
44.42500, 0.50, 280.0, 16.7332
44.47500, 0.50, 231.0, 15.1987
44.52500, 0.50, 155.0, 12.4499
44.57500, 0.50, 112.0, 10.5830
44.62500, 0.50, 94.0, 9.6954
44.67500, 0.50, 50.0, 7.0711
44.72500, 0.50, 38.0, 6.1644
44.77500, 0.50, 48.0, 6.9282
44.82500, 0.50, 43.0, 6.5574
44.87500, 0.50, 40.0, 6.3246
44.92500, 0.50, 26.0, 5.0990
44.97500, 0.50, 29.0, 5.3852
45.02500, 0.50, 21.0, 4.5826
45.07500, 0.50, 21.0, 4.5826
45.12500, 0.50, 20.0, 4.4721
45.17500, 0.50, 31.0, 5.5678
45.22500, 0.50, 24.0, 4.8990
45.27500, 0.50, 17.0, 4.1231
45.32500, 0.50, 19.0, 4.3589
45.37500, 0.50, 15.0, 3.8730
45.42500, 0.50, 16.0, 4.0000
45.47500, 0.50, 17.0, 4.1231
45.52500, 0.50, 23.0, 4.7958
45.57500, 0.50, 14.0, 3.7417
45.62500, 0.50, 18.0, 4.2426
45.67500, 0.50, 8.0, 2.8284
45.72500, 0.50, 12.0, 3.4641
45.77500, 0.50, 20.0, 4.4721
45.82500, 0.50, 16.0, 4.0000
45.87500, 0.50, 16.0, 4.0000
45.92500, 0.50, 11.0, 3.3166
45.97500, 0.50, 16.0, 4.0000
46.02500, 0.50, 9.0, 3.0000
46.07500, 0.50, 16.0, 4.0000
46.12500, 0.50, 19.0, 4.3589
46.17500, 0.50, 8.0, 2.8284
46.22500, 0.50, 15.0, 3.8730
46.27500, 0.50, 20.0, 4.4721
46.32500, 0.50, 16.0, 4.0000
46.37500, 0.50, 13.0, 3.6056
46.42500, 0.50, 14.0, 3.7417
46.47500, 0.50, 8.0, 2.8284
46.52500, 0.50, 7.0, 2.6458
46.57500, 0.50, 19.0, 4.3589
46.62500, 0.50, 16.0, 4.0000
46.67500, 0.50, 19.0, 4.3589
46.72500, 0.50, 13.0, 3.6056
46.77500, 0.50, 10.0, 3.1623
46.82500, 0.50, 8.0, 2.8284
46.87500, 0.50, 14.0, 3.7417
46.92500, 0.50, 10.0, 3.1623
46.97500, 0.50, 16.0, 4.0000
47.02500, 0.50, 11.0, 3.3166
47.07500, 0.50, 11.0, 3.3166
47.12500, 0.50, 14.0, 3.7417
47.17500, 0.50, 12.0, 3.4641
47.22500, 0.50, 12.0, 3.4641
47.27500, 0.50, 11.0, 3.3166
47.32500, 0.50, 14.0, 3.7417
47.37500, 0.50, 11.0, 3.3166
47.42500, 0.50, 13.0, 3.6056
47.47500, 0.50, 6.0, 2.4495
47.52500, 0.50, 15.0, 3.8730
47.57500, 0.50, 8.0, 2.8284
47.62500, 0.50, 10.0, 3.1623
47.67500, 0.50, 7.0, 2.6458
47.72500, 0.50, 10.0, 3.1623
47.77500, 0.50, 8.0, 2.8284
47.82500, 0.50, 5.0, 2.2361
47.87500, 0.50, 14.0, 3.7417
47.92500, 0.50, 15.0, 3.8730
47.97500, 0.50, 9.0, 3.0000
48.02500, 0.50, 4.0, 2.0000
48.07500, 0.50, 10.0, 3.1623
48.12500, 0.50, 5.0, 2.2361
48.17500, 0.50, 11.0, 3.3166
48.22500, 0.50, 9.0, 3.0000
48.27500, 0.50, 7.0, 2.6458
48.32500, 0.50, 7.0, 2.6458
48.37500, 0.50, 13.0, 3.6056
48.42500, 0.50, 20.0, 4.4721
48.47500, 0.50, 2.0, 1.4142
48.52500, 0.50, 8.0, 2.8284
48.57500, 0.50, 12.0, 3.4641
48.62500, 0.50, 7.0, 2.6458
48.67500, 0.50, 12.0, 3.4641
48.72500, 0.50, 9.0, 3.0000
48.77500, 0.50, 11.0, 3.3166
48.82500, 0.50, 9.0, 3.0000
48.87500, 0.50, 6.0, 2.4495
48.92500, 0.50, 17.0, 4.1231
48.97500, 0.50, 5.0, 2.2361
49.02500, 0.50, 10.0, 3.1623
49.07500, 0.50, 11.0, 3.3166
49.12500, 0.50, 10.0, 3.1623
49.17500, 0.50, 11.0, 3.3166
49.22500, 0.50, 6.0, 2.4495
49.27500, 0.50, 9.0, 3.0000
49.32500, 0.50, 9.0, 3.0000
49.37500, 0.50, 5.0, 2.2361
49.42500, 0.50, 10.0, 3.1623
49.47500, 0.50, 12.0, 3.4641
49.52500, 0.50, 7.0, 2.6458
49.57500, 0.50, 10.0, 3.1623
49.62500, 0.50, 10.0, 3.1623
49.67500, 0.50, 12.0, 3.4641
49.72500, 0.50, 11.0, 3.3166
49.77500, 0.50, 12.0, 3.4641
49.82500, 0.50, 1.0, 1.0000
49.87500, 0.50, 3.0, 1.7321
49.92500, 0.50, 4.0, 2.0000
49.97500, 0.50, 9.0, 3.0000
50.02500, 0.50, 5.0, 2.2361
50.07500, 0.50, 10.0, 3.1623
50.12500, 0.50, 8.0, 2.8284
50.17500, 0.50, 6.0, 2.4495
50.22500, 0.50, 8.0, 2.8284
50.27500, 0.50, 12.0, 3.4641
50.32500, 0.50, 9.0, 3.0000
50.37500, 0.50, 7.0, 2.6458
50.42500, 0.50, 5.0, 2.2361
50.47500, 0.50, 6.0, 2.4495
50.52500, 0.50, 11.0, 3.3166
50.57500, 0.50, 7.0, 2.6458
50.62500, 0.50, 12.0, 3.4641
50.67500, 0.50, 10.0, 3.1623
50.72500, 0.50, 14.0, 3.7417
50.77500, 0.50, 9.0, 3.0000
50.82500, 0.50, 11.0, 3.3166
50.87500, 0.50, 8.0, 2.8284
50.92500, 0.50, 7.0, 2.6458
50.97500, 0.50, 7.0, 2.6458
51.02500, 0.50, 10.0, 3.1623
51.07500, 0.50, 8.0, 2.8284
51.12500, 0.50, 14.0, 3.7417
51.17500, 0.50, 6.0, 2.4495
51.22500, 0.50, 11.0, 3.3166
51.27500, 0.50, 4.0, 2.0000
51.32500, 0.50, 6.0, 2.4495
51.37500, 0.50, 12.0, 3.4641
51.42500, 0.50, 7.0, 2.6458
51.47500, 0.50, 9.0, 3.0000
51.52500, 0.50, 4.0, 2.0000
51.57500, 0.50, 10.0, 3.1623
51.62500, 0.50, 6.0, 2.4495
51.67500, 0.50, 8.0, 2.8284
51.72500, 0.50, 15.0, 3.8730
51.77500, 0.50, 12.0, 3.4641
51.82500, 0.50, 7.0, 2.6458
51.87500, 0.50, 11.0, 3.3166
51.92500, 0.50, 8.0, 2.8284
51.97500, 0.50, 7.0, 2.6458
52.02500, 0.50, 8.0, 2.8284
52.07500, 0.50, 11.0, 3.3166
52.12500, 0.50, 8.0, 2.8284
52.17500, 0.50, 8.0, 2.8284
52.22500, 0.50, 7.0, 2.6458
52.27500, 0.50, 5.0, 2.2361
52.32500, 0.50, 8.0, 2.8284
52.37500, 0.50, 8.0, 2.8284
52.42500, 0.50, 9.0, 3.0000
52.47500, 0.50, 11.0, 3.3166
52.52500, 0.50, 4.0, 2.0000
52.57500, 0.50, 8.0, 2.8284
52.62500, 0.50, 8.0, 2.8284
52.67500, 0.50, 6.0, 2.4495
52.72500, 0.50, 7.0, 2.6458
52.77500, 0.50, 11.0, 3.3166
52.82500, 0.50, 10.0, 3.1623
52.87500, 0.50, 8.0, 2.8284
52.92500, 0.50, 5.0, 2.2361
52.97500, 0.50, 8.0, 2.8284
53.02500, 0.50, 8.0, 2.8284
53.07500, 0.50, 3.0, 1.7321
53.12500, 0.50, 8.0, 2.8284
53.17500, 0.50, 6.0, 2.4495
53.22500, 0.50, 7.0, 2.6458
53.27500, 0.50, 6.0, 2.4495
53.32500, 0.50, 13.0, 3.6056
53.37500, 0.50, 9.0, 3.0000
53.42500, 0.50, 9.0, 3.0000
53.47500, 0.50, 6.0, 2.4495
53.52500, 0.50, 7.0, 2.6458
53.57500, 0.50, 7.0, 2.6458
53.62500, 0.50, 3.0, 1.7321
53.67500, 0.50, 8.0, 2.8284
53.72500, 0.50, 5.0, 2.2361
53.77500, 0.50, 10.0, 3.1623
53.82500, 0.50, 10.0, 3.1623
53.87500, 0.50, 3.0, 1.7321
53.92500, 0.50, 9.0, 3.0000
53.97500, 0.50, 6.0, 2.4495
54.02500, 0.50, 8.0, 2.8284
54.07500, 0.50, 8.0, 2.8284
54.12500, 0.50, 7.0, 2.6458
54.17500, 0.50, 11.0, 3.3166
54.22500, 0.50, 7.0, 2.6458
54.27500, 0.50, 9.0, 3.0000
54.32500, 0.50, 6.0, 2.4495
54.37500, 0.50, 7.0, 2.6458
54.42500, 0.50, 10.0, 3.1623
54.47500, 0.50, 7.0, 2.6458
54.52500, 0.50, 8.0, 2.8284
54.57500, 0.50, 4.0, 2.0000
54.62500, 0.50, 9.0, 3.0000
54.67500, 0.50, 8.0, 2.8284
54.72500, 0.50, 7.0, 2.6458
54.77500, 0.50, 8.0, 2.8284
54.82500, 0.50, 2.0, 1.4142
54.87500, 0.50, 8.0, 2.8284
54.92500, 0.50, 6.0, 2.4495
54.97500, 0.50, 10.0, 3.1623
55.02500, 0.50, 5.0, 2.2361
55.07500, 0.50, 4.0, 2.0000
55.12500, 0.50, 8.0, 2.8284
55.17500, 0.50, 4.0, 2.0000
55.22500, 0.50, 8.0, 2.8284
55.27500, 0.50, 7.0, 2.6458
55.32500, 0.50, 7.0, 2.6458
55.37500, 0.50, 7.0, 2.6458
55.42500, 0.50, 7.0, 2.6458
55.47500, 0.50, 6.0, 2.4495
55.52500, 0.50, 9.0, 3.0000
55.57500, 0.50, 7.0, 2.6458
55.62500, 0.50, 6.0, 2.4495
55.67500, 0.50, 11.0, 3.3166
55.72500, 0.50, 6.0, 2.4495
55.77500, 0.50, 10.0, 3.1623
55.82500, 0.50, 4.0, 2.0000
55.87500, 0.50, 6.0, 2.4495
55.92500, 0.50, 4.0, 2.0000
55.97500, 0.50, 11.0, 3.3166
56.02500, 0.50, 8.0, 2.8284
56.07500, 0.50, 6.0, 2.4495
56.12500, 0.50, 7.0, 2.6458
56.17500, 0.50, 9.0, 3.0000
56.22500, 0.50, 6.0, 2.4495
56.27500, 0.50, 6.0, 2.4495
56.32500, 0.50, 4.0, 2.0000
56.37500, 0.50, 10.0, 3.1623
56.42500, 0.50, 4.0, 2.0000
56.47500, 0.50, 6.0, 2.4495
56.52500, 0.50, 5.0, 2.2361
56.57500, 0.50, 10.0, 3.1623
56.62500, 0.50, 5.0, 2.2361
56.67500, 0.50, 3.0, 1.7321
56.72500, 0.50, 3.0, 1.7321
56.77500, 0.50, 6.0, 2.4495
56.82500, 0.50, 6.0, 2.4495
56.87500, 0.50, 6.0, 2.4495
56.92500, 0.50, 9.0, 3.0000
56.97500, 0.50, 7.0, 2.6458
57.02500, 0.50, 9.0, 3.0000
57.07500, 0.50, 11.0, 3.3166
57.12500, 0.50, 7.0, 2.6458
57.17500, 0.50, 8.0, 2.8284
57.22500, 0.50, 7.0, 2.6458
57.27500, 0.50, 7.0, 2.6458
57.32500, 0.50, 8.0, 2.8284
57.37500, 0.50, 7.0, 2.6458
57.42500, 0.50, 5.0, 2.2361
57.47500, 0.50, 10.0, 3.1623
57.52500, 0.50, 5.0, 2.2361
57.57500, 0.50, 9.0, 3.0000
57.62500, 0.50, 5.0, 2.2361
57.67500, 0.50, 5.0, 2.2361
57.72500, 0.50, 11.0, 3.3166
57.77500, 0.50, 5.0, 2.2361
57.82500, 0.50, 11.0, 3.3166
57.87500, 0.50, 10.0, 3.1623
57.92500, 0.50, 4.0, 2.0000
57.97500, 0.50, 8.0, 2.8284
58.02500, 0.50, 7.0, 2.6458
58.07500, 0.50, 6.0, 2.4495
58.12500, 0.50, 9.0, 3.0000
58.17500, 0.50, 5.0, 2.2361
58.22500, 0.50, 6.0, 2.4495
58.27500, 0.50, 6.0, 2.4495
58.32500, 0.50, 6.0, 2.4495
58.37500, 0.50, 6.0, 2.4495
58.42500, 0.50, 8.0, 2.8284
58.47500, 0.50, 8.0, 2.8284
58.52500, 0.50, 6.0, 2.4495
58.57500, 0.50, 6.0, 2.4495
58.62500, 0.50, 9.0, 3.0000
58.67500, 0.50, 5.0, 2.2361
58.72500, 0.50, 10.0, 3.1623
58.77500, 0.50, 11.0, 3.3166
58.82500, 0.50, 6.0, 2.4495
58.87500, 0.50, 4.0, 2.0000
58.92500, 0.50, 5.0, 2.2361
58.97500, 0.50, 7.0, 2.6458
59.02500, 0.50, 10.0, 3.1623
59.07500, 0.50, 6.0, 2.4495
59.12500, 0.50, 4.0, 2.0000
59.17500, 0.50, 6.0, 2.4495
59.22500, 0.50, 12.0, 3.4641
59.27500, 0.50, 5.0, 2.2361
59.32500, 0.50, 9.0, 3.0000
59.37500, 0.50, 5.0, 2.2361
59.42500, 0.50, 7.0, 2.6458
59.47500, 0.50, 8.0, 2.8284
59.52500, 0.50, 5.0, 2.2361
59.57500, 0.50, 2.0, 1.4142
59.62500, 0.50, 5.0, 2.2361
59.67500, 0.50, 1.0, 1.0000
59.72500, 0.50, 8.0, 2.8284
59.77500, 0.50, 4.0, 2.0000
59.82500, 0.50, 5.0, 2.2361
59.87500, 0.50, 5.0, 2.2361
59.92500, 0.50, 6.0, 2.4495
59.97500, 0.50, 8.0, 2.8284
60.02500, 0.50, 12.0, 3.4641
60.07500, 0.50, 12.0, 3.4641
60.12500, 0.50, 5.0, 2.2361
60.17500, 0.50, 6.0, 2.4495
60.22500, 0.50, 2.0, 1.4142
60.27500, 0.50, 8.0, 2.8284
60.32500, 0.50, 7.0, 2.6458
60.37500, 0.50, 6.0, 2.4495
60.42500, 0.50, 7.0, 2.6458
60.47500, 0.50, 1.0, 1.0000
60.52500, 0.50, 3.0, 1.7321
60.57500, 0.50, 6.0, 2.4495
60.62500, 0.50, 5.0, 2.2361
60.67500, 0.50, 9.0, 3.0000
60.72500, 0.50, 7.0, 2.6458
60.77500, 0.50, 6.0, 2.4495
60.82500, 0.50, 6.0, 2.4495
60.87500, 0.50, 7.0, 2.6458
60.92500, 0.50, 6.0, 2.4495
60.97500, 0.50, 6.0, 2.4495
61.02500, 0.50, 8.0, 2.8284
61.07500, 0.50, 9.0, 3.0000
61.12500, 0.50, 6.0, 2.4495
61.17500, 0.50, 6.0, 2.4495
61.22500, 0.50, 6.0, 2.4495
61.27500, 0.50, 6.0, 2.4495
61.32500, 0.50, 6.0, 2.4495
61.37500, 0.50, 10.0, 3.1623
61.42500, 0.50, 9.0, 3.0000
61.47500, 0.50, 7.0, 2.6458
61.52500, 0.50, 3.0, 1.7321
61.57500, 0.50, 8.0, 2.8284
61.62500, 0.50, 12.0, 3.4641
61.67500, 0.50, 5.0, 2.2361
61.72500, 0.50, 8.0, 2.8284
61.77500, 0.50, 8.0, 2.8284
61.82500, 0.50, 8.0, 2.8284
61.87500, 0.50, 8.0, 2.8284
61.92500, 0.50, 8.0, 2.8284
61.97500, 0.50, 12.0, 3.4641
62.02500, 0.50, 6.0, 2.4495
62.07500, 0.50, 6.0, 2.4495
62.12500, 0.50, 8.0, 2.8284
62.17500, 0.50, 7.0, 2.6458
62.22500, 0.50, 5.0, 2.2361
62.27500, 0.50, 7.0, 2.6458
62.32500, 0.50, 11.0, 3.3166
62.37500, 0.50, 9.0, 3.0000
62.42500, 0.50, 6.0, 2.4495
62.47500, 0.50, 2.0, 1.4142
62.52500, 0.50, 10.0, 3.1623
62.57500, 0.50, 11.0, 3.3166
62.62500, 0.50, 7.0, 2.6458
62.67500, 0.50, 11.0, 3.3166
62.72500, 0.50, 7.0, 2.6458
62.77500, 0.50, 10.0, 3.1623
62.82500, 0.50, 9.0, 3.0000
62.87500, 0.50, 13.0, 3.6056
62.92500, 0.50, 8.0, 2.8284
62.97500, 0.50, 9.0, 3.0000
63.02500, 0.50, 7.0, 2.6458
63.07500, 0.50, 5.0, 2.2361
63.12500, 0.50, 7.0, 2.6458
63.17500, 0.50, 10.0, 3.1623
63.22500, 0.50, 10.0, 3.1623
63.27500, 0.50, 6.0, 2.4495
63.32500, 0.50, 11.0, 3.3166
63.37500, 0.50, 14.0, 3.7417
63.42500, 0.50, 9.0, 3.0000
63.47500, 0.50, 11.0, 3.3166
63.52500, 0.50, 10.0, 3.1623
63.57500, 0.50, 11.0, 3.3166
63.62500, 0.50, 13.0, 3.6056
63.67500, 0.50, 17.0, 4.1231
63.72500, 0.50, 21.0, 4.5826
63.77500, 0.50, 18.0, 4.2426
63.82500, 0.50, 13.0, 3.6056
63.87500, 0.50, 23.0, 4.7958
63.92500, 0.50, 23.0, 4.7958
63.97500, 0.50, 17.0, 4.1231
64.02500, 0.50, 26.0, 5.0990
64.07500, 0.50, 37.0, 6.0828
64.12500, 0.50, 49.0, 7.0000
64.17500, 0.50, 65.0, 8.0623
64.22500, 0.50, 86.0, 9.2736
64.27500, 0.50, 119.0, 10.9087
64.32500, 0.50, 184.0, 13.5647
64.37500, 0.50, 194.0, 13.9284
64.42500, 0.50, 211.0, 14.5258
64.47500, 0.50, 210.0, 14.4914
64.52500, 0.50, 199.0, 14.1067
64.57500, 0.50, 147.0, 12.1244
64.62500, 0.50, 121.0, 11.0000
64.67500, 0.50, 106.0, 10.2956
64.72500, 0.50, 77.0, 8.7750
64.77500, 0.50, 46.0, 6.7823
64.82500, 0.50, 28.0, 5.2915
64.87500, 0.50, 29.0, 5.3852
64.92500, 0.50, 23.0, 4.7958
64.97500, 0.50, 24.0, 4.8990
65.02500, 0.50, 22.0, 4.6904
65.07500, 0.50, 16.0, 4.0000
65.12500, 0.50, 14.0, 3.7417
65.17500, 0.50, 12.0, 3.4641
65.22500, 0.50, 16.0, 4.0000
65.27500, 0.50, 9.0, 3.0000
65.32500, 0.50, 9.0, 3.0000
65.37500, 0.50, 16.0, 4.0000
65.42500, 0.50, 11.0, 3.3166
65.47500, 0.50, 10.0, 3.1623
65.52500, 0.50, 7.0, 2.6458
65.57500, 0.50, 7.0, 2.6458
65.62500, 0.50, 14.0, 3.7417
65.67500, 0.50, 7.0, 2.6458
65.72500, 0.50, 10.0, 3.1623
65.77500, 0.50, 10.0, 3.1623
65.82500, 0.50, 7.0, 2.6458
65.87500, 0.50, 6.0, 2.4495
65.92500, 0.50, 9.0, 3.0000
65.97500, 0.50, 12.0, 3.4641
66.02500, 0.50, 8.0, 2.8284
66.07500, 0.50, 7.0, 2.6458
66.12500, 0.50, 13.0, 3.6056
66.17500, 0.50, 10.0, 3.1623
66.22500, 0.50, 3.0, 1.7321
66.27500, 0.50, 7.0, 2.6458
66.32500, 0.50, 11.0, 3.3166
66.37500, 0.50, 7.0, 2.6458
66.42500, 0.50, 7.0, 2.6458
66.47500, 0.50, 6.0, 2.4495
66.52500, 0.50, 8.0, 2.8284
66.57500, 0.50, 11.0, 3.3166
66.62500, 0.50, 7.0, 2.6458
66.67500, 0.50, 4.0, 2.0000
66.72500, 0.50, 3.0, 1.7321
66.77500, 0.50, 5.0, 2.2361
66.82500, 0.50, 6.0, 2.4495
66.87500, 0.50, 10.0, 3.1623
66.92500, 0.50, 7.0, 2.6458
66.97500, 0.50, 6.0, 2.4495
67.02500, 0.50, 9.0, 3.0000
67.07500, 0.50, 9.0, 3.0000
67.12500, 0.50, 9.0, 3.0000
67.17500, 0.50, 4.0, 2.0000
67.22500, 0.50, 8.0, 2.8284
67.27500, 0.50, 13.0, 3.6056
67.32500, 0.50, 6.0, 2.4495
67.37500, 0.50, 5.0, 2.2361
67.42500, 0.50, 6.0, 2.4495
67.47500, 0.50, 6.0, 2.4495
67.52500, 0.50, 10.0, 3.1623
67.57500, 0.50, 4.0, 2.0000
67.62500, 0.50, 9.0, 3.0000
67.67500, 0.50, 4.0, 2.0000
67.72500, 0.50, 4.0, 2.0000
67.77500, 0.50, 4.0, 2.0000
67.82500, 0.50, 4.0, 2.0000
67.87500, 0.50, 4.0, 2.0000
67.92500, 0.50, 5.0, 2.2361
67.97500, 0.50, 7.0, 2.6458
68.02500, 0.50, 7.0, 2.6458
68.07500, 0.50, 8.0, 2.8284
68.12500, 0.50, 3.0, 1.7321
68.17500, 0.50, 2.0, 1.4142
68.22500, 0.50, 7.0, 2.6458
68.27500, 0.50, 5.0, 2.2361
68.32500, 0.50, 5.0, 2.2361
68.37500, 0.50, 9.0, 3.0000
68.42500, 0.50, 11.0, 3.3166
68.47500, 0.50, 8.0, 2.8284
68.52500, 0.50, 3.0, 1.7321
68.57500, 0.50, 5.0, 2.2361
68.62500, 0.50, 9.0, 3.0000
68.67500, 0.50, 3.0, 1.7321
68.72500, 0.50, 4.0, 2.0000
68.77500, 0.50, 6.0, 2.4495
68.82500, 0.50, 5.0, 2.2361
68.87500, 0.50, 5.0, 2.2361
68.92500, 0.50, 3.0, 1.7321
68.97500, 0.50, 7.0, 2.6458
69.02500, 0.50, 7.0, 2.6458
69.07500, 0.50, 5.0, 2.2361
69.12500, 0.50, 2.0, 1.4142
69.17500, 0.50, 8.0, 2.8284
69.22500, 0.50, 4.0, 2.0000
69.27500, 0.50, 7.0, 2.6458
69.32500, 0.50, 1.0, 1.0000
69.37500, 0.50, 6.0, 2.4495
69.42500, 0.50, 2.0, 1.4142
69.47500, 0.50, 5.0, 2.2361
69.52500, 0.50, 7.0, 2.6458
69.57500, 0.50, 9.0, 3.0000
69.62500, 0.50, 8.0, 2.8284
69.67500, 0.50, 9.0, 3.0000
69.72500, 0.50, 5.0, 2.2361
69.77500, 0.50, 14.0, 3.7417
69.82500, 0.50, 2.0, 1.4142
69.87500, 0.50, 5.0, 2.2361
69.92500, 0.50, 5.0, 2.2361
69.97500, 0.50, 6.0, 2.4495
70.02500, 0.50, 6.0, 2.4495
70.07500, 0.50, 5.0, 2.2361
70.12500, 0.50, 3.0, 1.7321
70.17500, 0.50, 4.0, 2.0000
70.22500, 0.50, 6.0, 2.4495
70.27500, 0.50, 5.0, 2.2361
70.32500, 0.50, 5.0, 2.2361
70.37500, 0.50, 3.0, 1.7321
70.42500, 0.50, 2.0, 1.4142
70.47500, 0.50, 4.0, 2.0000
70.52500, 0.50, 5.0, 2.2361
70.57500, 0.50, 7.0, 2.6458
70.62500, 0.50, 9.0, 3.0000
70.67500, 0.50, 3.0, 1.7321
70.72500, 0.50, 2.0, 1.4142
70.77500, 0.50, 4.0, 2.0000
70.82500, 0.50, 6.0, 2.4495
70.87500, 0.50, 6.0, 2.4495
70.92500, 0.50, 6.0, 2.4495
70.97500, 0.50, 2.0, 1.4142
71.02500, 0.50, 6.0, 2.4495
71.07500, 0.50, 6.0, 2.4495
71.12500, 0.50, 3.0, 1.7321
71.17500, 0.50, 5.0, 2.2361
71.22500, 0.50, 3.0, 1.7321
71.27500, 0.50, 11.0, 3.3166
71.32500, 0.50, 2.0, 1.4142
71.37500, 0.50, 6.0, 2.4495
71.42500, 0.50, 4.0, 2.0000
71.47500, 0.50, 7.0, 2.6458
71.52500, 0.50, 6.0, 2.4495
71.57500, 0.50, 13.0, 3.6056
71.62500, 0.50, 9.0, 3.0000
71.67500, 0.50, 3.0, 1.7321
71.72500, 0.50, 2.0, 1.4142
71.77500, 0.50, 4.0, 2.0000
71.82500, 0.50, 5.0, 2.2361
71.87500, 0.50, 10.0, 3.1623
71.92500, 0.50, 5.0, 2.2361
71.97500, 0.50, 5.0, 2.2361
72.02500, 0.50, 9.0, 3.0000
72.07500, 0.50, 12.0, 3.4641
72.12500, 0.50, 6.0, 2.4495
72.17500, 0.50, 5.0, 2.2361
72.22500, 0.50, 5.0, 2.2361
72.27500, 0.50, 7.0, 2.6458
72.32500, 0.50, 7.0, 2.6458
72.37500, 0.50, 9.0, 3.0000
72.42500, 0.50, 9.0, 3.0000
72.47500, 0.50, 10.0, 3.1623
72.52500, 0.50, 5.0, 2.2361
72.57500, 0.50, 5.0, 2.2361
72.62500, 0.50, 3.0, 1.7321
72.67500, 0.50, 6.0, 2.4495
72.72500, 0.50, 7.0, 2.6458
72.77500, 0.50, 8.0, 2.8284
72.82500, 0.50, 5.0, 2.2361
72.87500, 0.50, 5.0, 2.2361
72.92500, 0.50, 1.0, 1.0000
72.97500, 0.50, 11.0, 3.3166
73.02500, 0.50, 6.0, 2.4495
73.07500, 0.50, 11.0, 3.3166
73.12500, 0.50, 10.0, 3.1623
73.17500, 0.50, 7.0, 2.6458
73.22500, 0.50, 5.0, 2.2361
73.27500, 0.50, 12.0, 3.4641
73.32500, 0.50, 6.0, 2.4495
73.37500, 0.50, 3.0, 1.7321
73.42500, 0.50, 3.0, 1.7321
73.47500, 0.50, 3.0, 1.7321
73.52500, 0.50, 6.0, 2.4495
73.57500, 0.50, 8.0, 2.8284
73.62500, 0.50, 4.0, 2.0000
73.67500, 0.50, 6.0, 2.4495
73.72500, 0.50, 8.0, 2.8284
73.77500, 0.50, 2.0, 1.4142
73.82500, 0.50, 1.0, 1.0000
73.87500, 0.50, 4.0, 2.0000
73.92500, 0.50, 6.0, 2.4495
73.97500, 0.50, 8.0, 2.8284
74.02500, 0.50, 7.0, 2.6458
74.07500, 0.50, 8.0, 2.8284
74.12500, 0.50, 4.0, 2.0000
74.17500, 0.50, 5.0, 2.2361
74.22500, 0.50, 9.0, 3.0000
74.27500, 0.50, 6.0, 2.4495
74.32500, 0.50, 8.0, 2.8284
74.37500, 0.50, 4.0, 2.0000
74.42500, 0.50, 3.0, 1.7321
74.47500, 0.50, 8.0, 2.8284
74.52500, 0.50, 7.0, 2.6458
74.57500, 0.50, 4.0, 2.0000
74.62500, 0.50, 6.0, 2.4495
74.67500, 0.50, 13.0, 3.6056
74.72500, 0.50, 7.0, 2.6458
74.77500, 0.50, 5.0, 2.2361
74.82500, 0.50, 9.0, 3.0000
74.87500, 0.50, 11.0, 3.3166
74.92500, 0.50, 8.0, 2.8284
74.97500, 0.50, 2.0, 1.4142
75.02500, 0.50, 10.0, 3.1623
75.07500, 0.50, 7.0, 2.6458
75.12500, 0.50, 6.0, 2.4495
75.17500, 0.50, 2.0, 1.4142
75.22500, 0.50, 3.0, 1.7321
75.27500, 0.50, 5.0, 2.2361
75.32500, 0.50, 7.0, 2.6458
75.37500, 0.50, 8.0, 2.8284
75.42500, 0.50, 5.0, 2.2361
75.47500, 0.50, 7.0, 2.6458
75.52500, 0.50, 8.0, 2.8284
75.57500, 0.50, 7.0, 2.6458
75.62500, 0.50, 8.0, 2.8284
75.67500, 0.50, 9.0, 3.0000
75.72500, 0.50, 8.0, 2.8284
75.77500, 0.50, 8.0, 2.8284
75.82500, 0.50, 5.0, 2.2361
75.87500, 0.50, 8.0, 2.8284
75.92500, 0.50, 8.0, 2.8284
75.97500, 0.50, 8.0, 2.8284
76.02500, 0.50, 10.0, 3.1623
76.07500, 0.50, 10.0, 3.1623
76.12500, 0.50, 5.0, 2.2361
76.17500, 0.50, 8.0, 2.8284
76.22500, 0.50, 8.0, 2.8284
76.27500, 0.50, 11.0, 3.3166
76.32500, 0.50, 13.0, 3.6056
76.37500, 0.50, 11.0, 3.3166
76.42500, 0.50, 4.0, 2.0000
76.47500, 0.50, 8.0, 2.8284
76.52500, 0.50, 17.0, 4.1231
76.57500, 0.50, 15.0, 3.8730
76.62500, 0.50, 13.0, 3.6056
76.67500, 0.50, 19.0, 4.3589
76.72500, 0.50, 23.0, 4.7958
76.77500, 0.50, 23.0, 4.7958
76.82500, 0.50, 20.0, 4.4721
76.87500, 0.50, 22.0, 4.6904
76.92500, 0.50, 25.0, 5.0000
76.97500, 0.50, 24.0, 4.8990
77.02500, 0.50, 39.0, 6.2450
77.07500, 0.50, 67.0, 8.1854
77.12500, 0.50, 80.0, 8.9443
77.17500, 0.50, 96.0, 9.7980
77.22500, 0.50, 111.0, 10.5357
77.27500, 0.50, 139.0, 11.7898
77.32500, 0.50, 188.0, 13.7113
77.37500, 0.50, 190.0, 13.7840
77.42500, 0.50, 171.0, 13.0767
77.47500, 0.50, 167.0, 12.9228
77.52500, 0.50, 154.0, 12.4097
77.57500, 0.50, 130.0, 11.4018
77.62500, 0.50, 124.0, 11.1355
77.67500, 0.50, 100.0, 10.0000
77.72500, 0.50, 83.0, 9.1104
77.77500, 0.50, 43.0, 6.5574
77.82500, 0.50, 49.0, 7.0000
77.87500, 0.50, 28.0, 5.2915
77.92500, 0.50, 25.0, 5.0000
77.97500, 0.50, 22.0, 4.6904
78.02500, 0.50, 24.0, 4.8990
78.07500, 0.50, 15.0, 3.8730
78.12500, 0.50, 17.0, 4.1231
78.17500, 0.50, 15.0, 3.8730
78.22500, 0.50, 17.0, 4.1231
78.27500, 0.50, 15.0, 3.8730
78.32500, 0.50, 8.0, 2.8284
78.37500, 0.50, 10.0, 3.1623
78.42500, 0.50, 9.0, 3.0000
78.47500, 0.50, 7.0, 2.6458
78.52500, 0.50, 5.0, 2.2361
78.57500, 0.50, 10.0, 3.1623
78.62500, 0.50, 8.0, 2.8284
78.67500, 0.50, 11.0, 3.3166
78.72500, 0.50, 11.0, 3.3166
78.77500, 0.50, 8.0, 2.8284
78.82500, 0.50, 11.0, 3.3166
78.87500, 0.50, 8.0, 2.8284
78.92500, 0.50, 6.0, 2.4495
78.97500, 0.50, 9.0, 3.0000
79.02500, 0.50, 10.0, 3.1623
79.07500, 0.50, 7.0, 2.6458
79.12500, 0.50, 5.0, 2.2361
79.17500, 0.50, 12.0, 3.4641
79.22500, 0.50, 6.0, 2.4495
79.27500, 0.50, 7.0, 2.6458
79.32500, 0.50, 8.0, 2.8284
79.37500, 0.50, 10.0, 3.1623
79.42500, 0.50, 2.0, 1.4142
79.47500, 0.50, 4.0, 2.0000
79.52500, 0.50, 11.0, 3.3166
79.57500, 0.50, 7.0, 2.6458
79.62500, 0.50, 4.0, 2.0000
79.67500, 0.50, 6.0, 2.4495
79.72500, 0.50, 9.0, 3.0000
79.77500, 0.50, 5.0, 2.2361
79.82500, 0.50, 8.0, 2.8284
79.87500, 0.50, 10.0, 3.1623
79.92500, 0.50, 4.0, 2.0000
79.97500, 0.50, 7.0, 2.6458