File: G03830.csv
[Measurement conditions]
Sample identification,Ag-EA 1layer on glass
Comment - 1,"Configuration=Programmable xy with programmable z platforms, Owner=User, Creation date=02/07/2021 13:22:25"
Comment - 2,"Goniometer=Theta/Theta; Minimum step size 2Theta:0.0001; Minimum step size Omega:0.0001"
Comment - 3,"Sample stage=Programmable xy-platform with programmable z-adjustment; Minimum step size X:0.01; Minimum step size Y:0.01; Minimum step size Z:0.001"
Comment - 4,"Diffractometer system=EMPYREAN"
Comment - 5,"Measurement program=C:\PANalytical\Data Collector\Programs\Knapp Group (CK)\Songming Liu\20-80°, 0.05° step, 0.5s-step.xrdmp, Created identifier={D6D0720B-9417-4404-86A5-80CEFF14CAE1}, Created by=User, Id=WL:EMPYREANGI:User, Creation date=20/06/2024 10:10:34"
Anode material,Cu
K-Alpha1 wavelength,1.5405980
K-Alpha2 wavelength,1.5444260
Ratio K-Alpha2/K-Alpha1,0.500
Divergence slit,Fixed,0.76mm
Monochromator used,NO
Generator voltage, 40
Tube current, 40
File date and time,20/Jun/2024 10:14
Unit cell,
h k l, 0 0 0
Scan axis,2Theta
Scan range,20.00000,80.00000
Scan step size,0.0500000
No. of points, 1200
Scan type,CONTINUOUS
Omega,1.0000
X,-0.01
Y,0.81
Z,20.313
Time per step,0.50
[Scan points]
Angle, TimePerStep, Intensity, ESD
20.02500, 0.50, 98.0, 9.8995
20.07500, 0.50, 112.0, 10.5830
20.12500, 0.50, 108.0, 10.3923
20.17500, 0.50, 121.0, 11.0000
20.22500, 0.50, 98.0, 9.8995
20.27500, 0.50, 112.0, 10.5830
20.32500, 0.50, 114.0, 10.6771
20.37500, 0.50, 132.0, 11.4891
20.42500, 0.50, 102.0, 10.0995
20.47500, 0.50, 105.0, 10.2470
20.52500, 0.50, 104.0, 10.1980
20.57500, 0.50, 90.0, 9.4868
20.62500, 0.50, 116.0, 10.7703
20.67500, 0.50, 112.0, 10.5830
20.72500, 0.50, 115.0, 10.7238
20.77500, 0.50, 83.0, 9.1104
20.82500, 0.50, 86.0, 9.2736
20.87500, 0.50, 105.0, 10.2470
20.92500, 0.50, 101.0, 10.0499
20.97500, 0.50, 106.0, 10.2956
21.02500, 0.50, 111.0, 10.5357
21.07500, 0.50, 118.0, 10.8628
21.12500, 0.50, 89.0, 9.4340
21.17500, 0.50, 107.0, 10.3441
21.22500, 0.50, 108.0, 10.3923
21.27500, 0.50, 118.0, 10.8628
21.32500, 0.50, 95.0, 9.7468
21.37500, 0.50, 91.0, 9.5394
21.42500, 0.50, 93.0, 9.6437
21.47500, 0.50, 93.0, 9.6437
21.52500, 0.50, 126.0, 11.2250
21.57500, 0.50, 95.0, 9.7468
21.62500, 0.50, 94.0, 9.6954
21.67500, 0.50, 88.0, 9.3808
21.72500, 0.50, 117.0, 10.8167
21.77500, 0.50, 116.0, 10.7703
21.82500, 0.50, 95.0, 9.7468
21.87500, 0.50, 109.0, 10.4403
21.92500, 0.50, 106.0, 10.2956
21.97500, 0.50, 109.0, 10.4403
22.02500, 0.50, 100.0, 10.0000
22.07500, 0.50, 109.0, 10.4403
22.12500, 0.50, 114.0, 10.6771
22.17500, 0.50, 110.0, 10.4881
22.22500, 0.50, 90.0, 9.4868
22.27500, 0.50, 102.0, 10.0995
22.32500, 0.50, 119.0, 10.9087
22.37500, 0.50, 124.0, 11.1355
22.42500, 0.50, 100.0, 10.0000
22.47500, 0.50, 110.0, 10.4881
22.52500, 0.50, 108.0, 10.3923
22.57500, 0.50, 94.0, 9.6954
22.62500, 0.50, 87.0, 9.3274
22.67500, 0.50, 81.0, 9.0000
22.72500, 0.50, 112.0, 10.5830
22.77500, 0.50, 106.0, 10.2956
22.82500, 0.50, 102.0, 10.0995
22.87500, 0.50, 100.0, 10.0000
22.92500, 0.50, 92.0, 9.5917
22.97500, 0.50, 84.0, 9.1652
23.02500, 0.50, 105.0, 10.2470
23.07500, 0.50, 108.0, 10.3923
23.12500, 0.50, 85.0, 9.2195
23.17500, 0.50, 99.0, 9.9499
23.22500, 0.50, 90.0, 9.4868
23.27500, 0.50, 93.0, 9.6437
23.32500, 0.50, 101.0, 10.0499
23.37500, 0.50, 114.0, 10.6771
23.42500, 0.50, 86.0, 9.2736
23.47500, 0.50, 104.0, 10.1980
23.52500, 0.50, 99.0, 9.9499
23.57500, 0.50, 105.0, 10.2470
23.62500, 0.50, 91.0, 9.5394
23.67500, 0.50, 110.0, 10.4881
23.72500, 0.50, 92.0, 9.5917
23.77500, 0.50, 86.0, 9.2736
23.82500, 0.50, 107.0, 10.3441
23.87500, 0.50, 91.0, 9.5394
23.92500, 0.50, 88.0, 9.3808
23.97500, 0.50, 89.0, 9.4340
24.02500, 0.50, 108.0, 10.3923
24.07500, 0.50, 89.0, 9.4340
24.12500, 0.50, 92.0, 9.5917
24.17500, 0.50, 95.0, 9.7468
24.22500, 0.50, 80.0, 8.9443
24.27500, 0.50, 108.0, 10.3923
24.32500, 0.50, 111.0, 10.5357
24.37500, 0.50, 90.0, 9.4868
24.42500, 0.50, 91.0, 9.5394
24.47500, 0.50, 108.0, 10.3923
24.52500, 0.50, 88.0, 9.3808
24.57500, 0.50, 78.0, 8.8318
24.62500, 0.50, 90.0, 9.4868
24.67500, 0.50, 76.0, 8.7178
24.72500, 0.50, 79.0, 8.8882
24.77500, 0.50, 90.0, 9.4868
24.82500, 0.50, 91.0, 9.5394
24.87500, 0.50, 84.0, 9.1652
24.92500, 0.50, 85.0, 9.2195
24.97500, 0.50, 81.0, 9.0000
25.02500, 0.50, 107.0, 10.3441
25.07500, 0.50, 82.0, 9.0554
25.12500, 0.50, 93.0, 9.6437
25.17500, 0.50, 106.0, 10.2956
25.22500, 0.50, 90.0, 9.4868
25.27500, 0.50, 84.0, 9.1652
25.32500, 0.50, 76.0, 8.7178
25.37500, 0.50, 79.0, 8.8882
25.42500, 0.50, 79.0, 8.8882
25.47500, 0.50, 75.0, 8.6603
25.52500, 0.50, 84.0, 9.1652
25.57500, 0.50, 71.0, 8.4261
25.62500, 0.50, 91.0, 9.5394
25.67500, 0.50, 63.0, 7.9373
25.72500, 0.50, 79.0, 8.8882
25.77500, 0.50, 76.0, 8.7178
25.82500, 0.50, 91.0, 9.5394
25.87500, 0.50, 87.0, 9.3274
25.92500, 0.50, 92.0, 9.5917
25.97500, 0.50, 70.0, 8.3666
26.02500, 0.50, 71.0, 8.4261
26.07500, 0.50, 62.0, 7.8740
26.12500, 0.50, 72.0, 8.4853
26.17500, 0.50, 79.0, 8.8882
26.22500, 0.50, 87.0, 9.3274
26.27500, 0.50, 75.0, 8.6603
26.32500, 0.50, 79.0, 8.8882
26.37500, 0.50, 73.0, 8.5440
26.42500, 0.50, 70.0, 8.3666
26.47500, 0.50, 71.0, 8.4261
26.52500, 0.50, 75.0, 8.6603
26.57500, 0.50, 66.0, 8.1240
26.62500, 0.50, 74.0, 8.6023
26.67500, 0.50, 61.0, 7.8102
26.72500, 0.50, 69.0, 8.3066
26.77500, 0.50, 61.0, 7.8102
26.82500, 0.50, 78.0, 8.8318
26.87500, 0.50, 76.0, 8.7178
26.92500, 0.50, 74.0, 8.6023
26.97500, 0.50, 66.0, 8.1240
27.02500, 0.50, 71.0, 8.4261
27.07500, 0.50, 69.0, 8.3066
27.12500, 0.50, 81.0, 9.0000
27.17500, 0.50, 64.0, 8.0000
27.22500, 0.50, 63.0, 7.9373
27.27500, 0.50, 51.0, 7.1414
27.32500, 0.50, 75.0, 8.6603
27.37500, 0.50, 69.0, 8.3066
27.42500, 0.50, 77.0, 8.7750
27.47500, 0.50, 65.0, 8.0623
27.52500, 0.50, 78.0, 8.8318
27.57500, 0.50, 79.0, 8.8882
27.62500, 0.50, 68.0, 8.2462
27.67500, 0.50, 60.0, 7.7460
27.72500, 0.50, 71.0, 8.4261
27.77500, 0.50, 54.0, 7.3485
27.82500, 0.50, 72.0, 8.4853
27.87500, 0.50, 66.0, 8.1240
27.92500, 0.50, 57.0, 7.5498
27.97500, 0.50, 70.0, 8.3666
28.02500, 0.50, 63.0, 7.9373
28.07500, 0.50, 59.0, 7.6811
28.12500, 0.50, 77.0, 8.7750
28.17500, 0.50, 64.0, 8.0000
28.22500, 0.50, 58.0, 7.6158
28.27500, 0.50, 63.0, 7.9373
28.32500, 0.50, 57.0, 7.5498
28.37500, 0.50, 69.0, 8.3066
28.42500, 0.50, 52.0, 7.2111
28.47500, 0.50, 61.0, 7.8102
28.52500, 0.50, 62.0, 7.8740
28.57500, 0.50, 63.0, 7.9373
28.62500, 0.50, 51.0, 7.1414
28.67500, 0.50, 60.0, 7.7460
28.72500, 0.50, 64.0, 8.0000
28.77500, 0.50, 69.0, 8.3066
28.82500, 0.50, 55.0, 7.4162
28.87500, 0.50, 67.0, 8.1854
28.92500, 0.50, 55.0, 7.4162
28.97500, 0.50, 57.0, 7.5498
29.02500, 0.50, 52.0, 7.2111
29.07500, 0.50, 62.0, 7.8740
29.12500, 0.50, 54.0, 7.3485
29.17500, 0.50, 55.0, 7.4162
29.22500, 0.50, 51.0, 7.1414
29.27500, 0.50, 40.0, 6.3246
29.32500, 0.50, 61.0, 7.8102
29.37500, 0.50, 49.0, 7.0000
29.42500, 0.50, 61.0, 7.8102
29.47500, 0.50, 53.0, 7.2801
29.52500, 0.50, 49.0, 7.0000
29.57500, 0.50, 48.0, 6.9282
29.62500, 0.50, 54.0, 7.3485
29.67500, 0.50, 58.0, 7.6158
29.72500, 0.50, 60.0, 7.7460
29.77500, 0.50, 49.0, 7.0000
29.82500, 0.50, 49.0, 7.0000
29.87500, 0.50, 60.0, 7.7460
29.92500, 0.50, 62.0, 7.8740
29.97500, 0.50, 54.0, 7.3485
30.02500, 0.50, 51.0, 7.1414
30.07500, 0.50, 51.0, 7.1414
30.12500, 0.50, 55.0, 7.4162
30.17500, 0.50, 66.0, 8.1240
30.22500, 0.50, 54.0, 7.3485
30.27500, 0.50, 53.0, 7.2801
30.32500, 0.50, 47.0, 6.8557
30.37500, 0.50, 51.0, 7.1414
30.42500, 0.50, 48.0, 6.9282
30.47500, 0.50, 48.0, 6.9282
30.52500, 0.50, 61.0, 7.8102
30.57500, 0.50, 65.0, 8.0623
30.62500, 0.50, 58.0, 7.6158
30.67500, 0.50, 59.0, 7.6811
30.72500, 0.50, 48.0, 6.9282
30.77500, 0.50, 60.0, 7.7460
30.82500, 0.50, 46.0, 6.7823
30.87500, 0.50, 50.0, 7.0711
30.92500, 0.50, 40.0, 6.3246
30.97500, 0.50, 36.0, 6.0000
31.02500, 0.50, 52.0, 7.2111
31.07500, 0.50, 53.0, 7.2801
31.12500, 0.50, 47.0, 6.8557
31.17500, 0.50, 56.0, 7.4833
31.22500, 0.50, 47.0, 6.8557
31.27500, 0.50, 54.0, 7.3485
31.32500, 0.50, 52.0, 7.2111
31.37500, 0.50, 41.0, 6.4031
31.42500, 0.50, 47.0, 6.8557
31.47500, 0.50, 48.0, 6.9282
31.52500, 0.50, 53.0, 7.2801
31.57500, 0.50, 47.0, 6.8557
31.62500, 0.50, 47.0, 6.8557
31.67500, 0.50, 42.0, 6.4807
31.72500, 0.50, 54.0, 7.3485
31.77500, 0.50, 40.0, 6.3246
31.82500, 0.50, 48.0, 6.9282
31.87500, 0.50, 46.0, 6.7823
31.92500, 0.50, 48.0, 6.9282
31.97500, 0.50, 44.0, 6.6332
32.02500, 0.50, 49.0, 7.0000
32.07500, 0.50, 27.0, 5.1962
32.12500, 0.50, 46.0, 6.7823
32.17500, 0.50, 35.0, 5.9161
32.22500, 0.50, 42.0, 6.4807
32.27500, 0.50, 44.0, 6.6332
32.32500, 0.50, 43.0, 6.5574
32.37500, 0.50, 39.0, 6.2450
32.42500, 0.50, 39.0, 6.2450
32.47500, 0.50, 37.0, 6.0828
32.52500, 0.50, 41.0, 6.4031
32.57500, 0.50, 47.0, 6.8557
32.62500, 0.50, 26.0, 5.0990
32.67500, 0.50, 39.0, 6.2450
32.72500, 0.50, 52.0, 7.2111
32.77500, 0.50, 39.0, 6.2450
32.82500, 0.50, 30.0, 5.4772
32.87500, 0.50, 39.0, 6.2450
32.92500, 0.50, 43.0, 6.5574
32.97500, 0.50, 41.0, 6.4031
33.02500, 0.50, 45.0, 6.7082
33.07500, 0.50, 33.0, 5.7446
33.12500, 0.50, 47.0, 6.8557
33.17500, 0.50, 35.0, 5.9161
33.22500, 0.50, 34.0, 5.8310
33.27500, 0.50, 32.0, 5.6569
33.32500, 0.50, 40.0, 6.3246
33.37500, 0.50, 34.0, 5.8310
33.42500, 0.50, 33.0, 5.7446
33.47500, 0.50, 39.0, 6.2450
33.52500, 0.50, 40.0, 6.3246
33.57500, 0.50, 34.0, 5.8310
33.62500, 0.50, 37.0, 6.0828
33.67500, 0.50, 40.0, 6.3246
33.72500, 0.50, 36.0, 6.0000
33.77500, 0.50, 41.0, 6.4031
33.82500, 0.50, 32.0, 5.6569
33.87500, 0.50, 33.0, 5.7446
33.92500, 0.50, 26.0, 5.0990
33.97500, 0.50, 45.0, 6.7082
34.02500, 0.50, 41.0, 6.4031
34.07500, 0.50, 36.0, 6.0000
34.12500, 0.50, 32.0, 5.6569
34.17500, 0.50, 45.0, 6.7082
34.22500, 0.50, 44.0, 6.6332
34.27500, 0.50, 50.0, 7.0711
34.32500, 0.50, 33.0, 5.7446
34.37500, 0.50, 47.0, 6.8557
34.42500, 0.50, 51.0, 7.1414
34.47500, 0.50, 28.0, 5.2915
34.52500, 0.50, 35.0, 5.9161
34.57500, 0.50, 34.0, 5.8310
34.62500, 0.50, 43.0, 6.5574
34.67500, 0.50, 30.0, 5.4772
34.72500, 0.50, 36.0, 6.0000
34.77500, 0.50, 31.0, 5.5678
34.82500, 0.50, 30.0, 5.4772
34.87500, 0.50, 43.0, 6.5574
34.92500, 0.50, 22.0, 4.6904
34.97500, 0.50, 35.0, 5.9161
35.02500, 0.50, 42.0, 6.4807
35.07500, 0.50, 52.0, 7.2111
35.12500, 0.50, 47.0, 6.8557
35.17500, 0.50, 49.0, 7.0000
35.22500, 0.50, 31.0, 5.5678
35.27500, 0.50, 28.0, 5.2915
35.32500, 0.50, 36.0, 6.0000
35.37500, 0.50, 35.0, 5.9161
35.42500, 0.50, 35.0, 5.9161
35.47500, 0.50, 46.0, 6.7823
35.52500, 0.50, 39.0, 6.2450
35.57500, 0.50, 35.0, 5.9161
35.62500, 0.50, 39.0, 6.2450
35.67500, 0.50, 45.0, 6.7082
35.72500, 0.50, 53.0, 7.2801
35.77500, 0.50, 44.0, 6.6332
35.82500, 0.50, 43.0, 6.5574
35.87500, 0.50, 36.0, 6.0000
35.92500, 0.50, 49.0, 7.0000
35.97500, 0.50, 36.0, 6.0000
36.02500, 0.50, 41.0, 6.4031
36.07500, 0.50, 43.0, 6.5574
36.12500, 0.50, 44.0, 6.6332
36.17500, 0.50, 54.0, 7.3485
36.22500, 0.50, 36.0, 6.0000
36.27500, 0.50, 38.0, 6.1644
36.32500, 0.50, 36.0, 6.0000
36.37500, 0.50, 54.0, 7.3485
36.42500, 0.50, 49.0, 7.0000
36.47500, 0.50, 60.0, 7.7460
36.52500, 0.50, 54.0, 7.3485
36.57500, 0.50, 52.0, 7.2111
36.62500, 0.50, 41.0, 6.4031
36.67500, 0.50, 47.0, 6.8557
36.72500, 0.50, 43.0, 6.5574
36.77500, 0.50, 43.0, 6.5574
36.82500, 0.50, 50.0, 7.0711
36.87500, 0.50, 45.0, 6.7082
36.92500, 0.50, 49.0, 7.0000
36.97500, 0.50, 46.0, 6.7823
37.02500, 0.50, 58.0, 7.6158
37.07500, 0.50, 59.0, 7.6811
37.12500, 0.50, 71.0, 8.4261
37.17500, 0.50, 71.0, 8.4261
37.22500, 0.50, 77.0, 8.7750
37.27500, 0.50, 80.0, 8.9443
37.32500, 0.50, 73.0, 8.5440
37.37500, 0.50, 88.0, 9.3808
37.42500, 0.50, 78.0, 8.8318
37.47500, 0.50, 107.0, 10.3441
37.52500, 0.50, 131.0, 11.4455
37.57500, 0.50, 140.0, 11.8322
37.62500, 0.50, 160.0, 12.6491
37.67500, 0.50, 194.0, 13.9284
37.72500, 0.50, 247.0, 15.7162
37.77500, 0.50, 297.0, 17.2337
37.82500, 0.50, 430.0, 20.7364
37.87500, 0.50, 605.0, 24.5967
37.92500, 0.50, 880.0, 29.6648
37.97500, 0.50, 1169.0, 34.1906
38.02500, 0.50, 1601.0, 40.0125
38.07500, 0.50, 2022.0, 44.9667
38.12500, 0.50, 2056.0, 45.3431
38.17500, 0.50, 1743.0, 41.7493
38.22500, 0.50, 1223.0, 34.9714
38.27500, 0.50, 824.0, 28.7054
38.32500, 0.50, 535.0, 23.1301
38.37500, 0.50, 353.0, 18.7883
38.42500, 0.50, 249.0, 15.7797
38.47500, 0.50, 185.0, 13.6015
38.52500, 0.50, 148.0, 12.1655
38.57500, 0.50, 140.0, 11.8322
38.62500, 0.50, 115.0, 10.7238
38.67500, 0.50, 112.0, 10.5830
38.72500, 0.50, 89.0, 9.4340
38.77500, 0.50, 99.0, 9.9499
38.82500, 0.50, 75.0, 8.6603
38.87500, 0.50, 79.0, 8.8882
38.92500, 0.50, 72.0, 8.4853
38.97500, 0.50, 77.0, 8.7750
39.02500, 0.50, 71.0, 8.4261
39.07500, 0.50, 51.0, 7.1414
39.12500, 0.50, 68.0, 8.2462
39.17500, 0.50, 56.0, 7.4833
39.22500, 0.50, 57.0, 7.5498
39.27500, 0.50, 53.0, 7.2801
39.32500, 0.50, 56.0, 7.4833
39.37500, 0.50, 44.0, 6.6332
39.42500, 0.50, 50.0, 7.0711
39.47500, 0.50, 49.0, 7.0000
39.52500, 0.50, 52.0, 7.2111
39.57500, 0.50, 46.0, 6.7823
39.62500, 0.50, 43.0, 6.5574
39.67500, 0.50, 53.0, 7.2801
39.72500, 0.50, 39.0, 6.2450
39.77500, 0.50, 36.0, 6.0000
39.82500, 0.50, 43.0, 6.5574
39.87500, 0.50, 48.0, 6.9282
39.92500, 0.50, 37.0, 6.0828
39.97500, 0.50, 38.0, 6.1644
40.02500, 0.50, 39.0, 6.2450
40.07500, 0.50, 37.0, 6.0828
40.12500, 0.50, 40.0, 6.3246
40.17500, 0.50, 27.0, 5.1962
40.22500, 0.50, 25.0, 5.0000
40.27500, 0.50, 39.0, 6.2450
40.32500, 0.50, 25.0, 5.0000
40.37500, 0.50, 25.0, 5.0000
40.42500, 0.50, 35.0, 5.9161
40.47500, 0.50, 41.0, 6.4031
40.52500, 0.50, 30.0, 5.4772
40.57500, 0.50, 35.0, 5.9161
40.62500, 0.50, 36.0, 6.0000
40.67500, 0.50, 45.0, 6.7082
40.72500, 0.50, 30.0, 5.4772
40.77500, 0.50, 28.0, 5.2915
40.82500, 0.50, 28.0, 5.2915
40.87500, 0.50, 36.0, 6.0000
40.92500, 0.50, 28.0, 5.2915
40.97500, 0.50, 32.0, 5.6569
41.02500, 0.50, 39.0, 6.2450
41.07500, 0.50, 38.0, 6.1644
41.12500, 0.50, 27.0, 5.1962
41.17500, 0.50, 26.0, 5.0990
41.22500, 0.50, 26.0, 5.0990
41.27500, 0.50, 29.0, 5.3852
41.32500, 0.50, 26.0, 5.0990
41.37500, 0.50, 28.0, 5.2915
41.42500, 0.50, 20.0, 4.4721
41.47500, 0.50, 25.0, 5.0000
41.52500, 0.50, 31.0, 5.5678
41.57500, 0.50, 28.0, 5.2915
41.62500, 0.50, 29.0, 5.3852
41.67500, 0.50, 34.0, 5.8310
41.72500, 0.50, 25.0, 5.0000
41.77500, 0.50, 44.0, 6.6332
41.82500, 0.50, 25.0, 5.0000
41.87500, 0.50, 26.0, 5.0990
41.92500, 0.50, 23.0, 4.7958
41.97500, 0.50, 31.0, 5.5678
42.02500, 0.50, 32.0, 5.6569
42.07500, 0.50, 21.0, 4.5826
42.12500, 0.50, 44.0, 6.6332
42.17500, 0.50, 29.0, 5.3852
42.22500, 0.50, 29.0, 5.3852
42.27500, 0.50, 32.0, 5.6569
42.32500, 0.50, 36.0, 6.0000
42.37500, 0.50, 32.0, 5.6569
42.42500, 0.50, 31.0, 5.5678
42.47500, 0.50, 26.0, 5.0990
42.52500, 0.50, 25.0, 5.0000
42.57500, 0.50, 37.0, 6.0828
42.62500, 0.50, 38.0, 6.1644
42.67500, 0.50, 29.0, 5.3852
42.72500, 0.50, 38.0, 6.1644
42.77500, 0.50, 28.0, 5.2915
42.82500, 0.50, 31.0, 5.5678
42.87500, 0.50, 28.0, 5.2915
42.92500, 0.50, 36.0, 6.0000
42.97500, 0.50, 29.0, 5.3852
43.02500, 0.50, 43.0, 6.5574
43.07500, 0.50, 40.0, 6.3246
43.12500, 0.50, 37.0, 6.0828
43.17500, 0.50, 48.0, 6.9282
43.22500, 0.50, 42.0, 6.4807
43.27500, 0.50, 48.0, 6.9282
43.32500, 0.50, 39.0, 6.2450
43.37500, 0.50, 46.0, 6.7823
43.42500, 0.50, 46.0, 6.7823
43.47500, 0.50, 46.0, 6.7823
43.52500, 0.50, 50.0, 7.0711
43.57500, 0.50, 67.0, 8.1854
43.62500, 0.50, 65.0, 8.0623
43.67500, 0.50, 66.0, 8.1240
43.72500, 0.50, 72.0, 8.4853
43.77500, 0.50, 94.0, 9.6954
43.82500, 0.50, 101.0, 10.0499
43.87500, 0.50, 123.0, 11.0905
43.92500, 0.50, 166.0, 12.8841
43.97500, 0.50, 180.0, 13.4164
44.02500, 0.50, 211.0, 14.5258
44.07500, 0.50, 288.0, 16.9706
44.12500, 0.50, 374.0, 19.3391
44.17500, 0.50, 476.0, 21.8174
44.22500, 0.50, 572.0, 23.9165
44.27500, 0.50, 602.0, 24.5357
44.32500, 0.50, 613.0, 24.7588
44.37500, 0.50, 526.0, 22.9347
44.42500, 0.50, 469.0, 21.6564
44.47500, 0.50, 340.0, 18.4391
44.52500, 0.50, 246.0, 15.6844
44.57500, 0.50, 182.0, 13.4907
44.62500, 0.50, 154.0, 12.4097
44.67500, 0.50, 101.0, 10.0499
44.72500, 0.50, 90.0, 9.4868
44.77500, 0.50, 75.0, 8.6603
44.82500, 0.50, 64.0, 8.0000
44.87500, 0.50, 58.0, 7.6158
44.92500, 0.50, 49.0, 7.0000
44.97500, 0.50, 40.0, 6.3246
45.02500, 0.50, 55.0, 7.4162
45.07500, 0.50, 30.0, 5.4772
45.12500, 0.50, 42.0, 6.4807
45.17500, 0.50, 41.0, 6.4031
45.22500, 0.50, 34.0, 5.8310
45.27500, 0.50, 22.0, 4.6904
45.32500, 0.50, 29.0, 5.3852
45.37500, 0.50, 28.0, 5.2915
45.42500, 0.50, 33.0, 5.7446
45.47500, 0.50, 27.0, 5.1962
45.52500, 0.50, 29.0, 5.3852
45.57500, 0.50, 27.0, 5.1962
45.62500, 0.50, 21.0, 4.5826
45.67500, 0.50, 21.0, 4.5826
45.72500, 0.50, 15.0, 3.8730
45.77500, 0.50, 23.0, 4.7958
45.82500, 0.50, 20.0, 4.4721
45.87500, 0.50, 18.0, 4.2426
45.92500, 0.50, 18.0, 4.2426
45.97500, 0.50, 21.0, 4.5826
46.02500, 0.50, 22.0, 4.6904
46.07500, 0.50, 18.0, 4.2426
46.12500, 0.50, 15.0, 3.8730
46.17500, 0.50, 18.0, 4.2426
46.22500, 0.50, 29.0, 5.3852
46.27500, 0.50, 15.0, 3.8730
46.32500, 0.50, 20.0, 4.4721
46.37500, 0.50, 12.0, 3.4641
46.42500, 0.50, 15.0, 3.8730
46.47500, 0.50, 19.0, 4.3589
46.52500, 0.50, 11.0, 3.3166
46.57500, 0.50, 15.0, 3.8730
46.62500, 0.50, 20.0, 4.4721
46.67500, 0.50, 19.0, 4.3589
46.72500, 0.50, 18.0, 4.2426
46.77500, 0.50, 16.0, 4.0000
46.82500, 0.50, 14.0, 3.7417
46.87500, 0.50, 14.0, 3.7417
46.92500, 0.50, 13.0, 3.6056
46.97500, 0.50, 23.0, 4.7958
47.02500, 0.50, 20.0, 4.4721
47.07500, 0.50, 20.0, 4.4721
47.12500, 0.50, 13.0, 3.6056
47.17500, 0.50, 10.0, 3.1623
47.22500, 0.50, 19.0, 4.3589
47.27500, 0.50, 14.0, 3.7417
47.32500, 0.50, 11.0, 3.3166
47.37500, 0.50, 14.0, 3.7417
47.42500, 0.50, 8.0, 2.8284
47.47500, 0.50, 11.0, 3.3166
47.52500, 0.50, 9.0, 3.0000
47.57500, 0.50, 19.0, 4.3589
47.62500, 0.50, 15.0, 3.8730
47.67500, 0.50, 10.0, 3.1623
47.72500, 0.50, 4.0, 2.0000
47.77500, 0.50, 12.0, 3.4641
47.82500, 0.50, 12.0, 3.4641
47.87500, 0.50, 10.0, 3.1623
47.92500, 0.50, 20.0, 4.4721
47.97500, 0.50, 11.0, 3.3166
48.02500, 0.50, 18.0, 4.2426
48.07500, 0.50, 12.0, 3.4641
48.12500, 0.50, 13.0, 3.6056
48.17500, 0.50, 9.0, 3.0000
48.22500, 0.50, 17.0, 4.1231
48.27500, 0.50, 13.0, 3.6056
48.32500, 0.50, 12.0, 3.4641
48.37500, 0.50, 10.0, 3.1623
48.42500, 0.50, 10.0, 3.1623
48.47500, 0.50, 12.0, 3.4641
48.52500, 0.50, 19.0, 4.3589
48.57500, 0.50, 15.0, 3.8730
48.62500, 0.50, 12.0, 3.4641
48.67500, 0.50, 11.0, 3.3166
48.72500, 0.50, 14.0, 3.7417
48.77500, 0.50, 8.0, 2.8284
48.82500, 0.50, 8.0, 2.8284
48.87500, 0.50, 8.0, 2.8284
48.92500, 0.50, 9.0, 3.0000
48.97500, 0.50, 17.0, 4.1231
49.02500, 0.50, 9.0, 3.0000
49.07500, 0.50, 9.0, 3.0000
49.12500, 0.50, 10.0, 3.1623
49.17500, 0.50, 10.0, 3.1623
49.22500, 0.50, 9.0, 3.0000
49.27500, 0.50, 16.0, 4.0000
49.32500, 0.50, 10.0, 3.1623
49.37500, 0.50, 11.0, 3.3166
49.42500, 0.50, 12.0, 3.4641
49.47500, 0.50, 24.0, 4.8990
49.52500, 0.50, 10.0, 3.1623
49.57500, 0.50, 5.0, 2.2361
49.62500, 0.50, 20.0, 4.4721
49.67500, 0.50, 13.0, 3.6056
49.72500, 0.50, 15.0, 3.8730
49.77500, 0.50, 17.0, 4.1231
49.82500, 0.50, 11.0, 3.3166
49.87500, 0.50, 8.0, 2.8284
49.92500, 0.50, 7.0, 2.6458
49.97500, 0.50, 9.0, 3.0000
50.02500, 0.50, 20.0, 4.4721
50.07500, 0.50, 7.0, 2.6458
50.12500, 0.50, 15.0, 3.8730
50.17500, 0.50, 8.0, 2.8284
50.22500, 0.50, 8.0, 2.8284
50.27500, 0.50, 8.0, 2.8284
50.32500, 0.50, 10.0, 3.1623
50.37500, 0.50, 7.0, 2.6458
50.42500, 0.50, 8.0, 2.8284
50.47500, 0.50, 9.0, 3.0000
50.52500, 0.50, 10.0, 3.1623
50.57500, 0.50, 4.0, 2.0000
50.62500, 0.50, 9.0, 3.0000
50.67500, 0.50, 6.0, 2.4495
50.72500, 0.50, 15.0, 3.8730
50.77500, 0.50, 6.0, 2.4495
50.82500, 0.50, 12.0, 3.4641
50.87500, 0.50, 10.0, 3.1623
50.92500, 0.50, 13.0, 3.6056
50.97500, 0.50, 10.0, 3.1623
51.02500, 0.50, 12.0, 3.4641
51.07500, 0.50, 12.0, 3.4641
51.12500, 0.50, 15.0, 3.8730
51.17500, 0.50, 7.0, 2.6458
51.22500, 0.50, 3.0, 1.7321
51.27500, 0.50, 5.0, 2.2361
51.32500, 0.50, 13.0, 3.6056
51.37500, 0.50, 8.0, 2.8284
51.42500, 0.50, 3.0, 1.7321
51.47500, 0.50, 8.0, 2.8284
51.52500, 0.50, 11.0, 3.3166
51.57500, 0.50, 10.0, 3.1623
51.62500, 0.50, 11.0, 3.3166
51.67500, 0.50, 16.0, 4.0000
51.72500, 0.50, 5.0, 2.2361
51.77500, 0.50, 12.0, 3.4641
51.82500, 0.50, 9.0, 3.0000
51.87500, 0.50, 10.0, 3.1623
51.92500, 0.50, 9.0, 3.0000
51.97500, 0.50, 8.0, 2.8284
52.02500, 0.50, 8.0, 2.8284
52.07500, 0.50, 12.0, 3.4641
52.12500, 0.50, 17.0, 4.1231
52.17500, 0.50, 9.0, 3.0000
52.22500, 0.50, 10.0, 3.1623
52.27500, 0.50, 12.0, 3.4641
52.32500, 0.50, 14.0, 3.7417
52.37500, 0.50, 13.0, 3.6056
52.42500, 0.50, 13.0, 3.6056
52.47500, 0.50, 6.0, 2.4495
52.52500, 0.50, 12.0, 3.4641
52.57500, 0.50, 4.0, 2.0000
52.62500, 0.50, 8.0, 2.8284
52.67500, 0.50, 11.0, 3.3166
52.72500, 0.50, 8.0, 2.8284
52.77500, 0.50, 13.0, 3.6056
52.82500, 0.50, 10.0, 3.1623
52.87500, 0.50, 10.0, 3.1623
52.92500, 0.50, 9.0, 3.0000
52.97500, 0.50, 9.0, 3.0000
53.02500, 0.50, 10.0, 3.1623
53.07500, 0.50, 7.0, 2.6458
53.12500, 0.50, 11.0, 3.3166
53.17500, 0.50, 7.0, 2.6458
53.22500, 0.50, 8.0, 2.8284
53.27500, 0.50, 8.0, 2.8284
53.32500, 0.50, 7.0, 2.6458
53.37500, 0.50, 9.0, 3.0000
53.42500, 0.50, 9.0, 3.0000
53.47500, 0.50, 10.0, 3.1623
53.52500, 0.50, 11.0, 3.3166
53.57500, 0.50, 6.0, 2.4495
53.62500, 0.50, 7.0, 2.6458
53.67500, 0.50, 8.0, 2.8284
53.72500, 0.50, 10.0, 3.1623
53.77500, 0.50, 8.0, 2.8284
53.82500, 0.50, 9.0, 3.0000
53.87500, 0.50, 9.0, 3.0000
53.92500, 0.50, 6.0, 2.4495
53.97500, 0.50, 6.0, 2.4495
54.02500, 0.50, 6.0, 2.4495
54.07500, 0.50, 7.0, 2.6458
54.12500, 0.50, 9.0, 3.0000
54.17500, 0.50, 8.0, 2.8284
54.22500, 0.50, 9.0, 3.0000
54.27500, 0.50, 10.0, 3.1623
54.32500, 0.50, 9.0, 3.0000
54.37500, 0.50, 10.0, 3.1623
54.42500, 0.50, 6.0, 2.4495
54.47500, 0.50, 8.0, 2.8284
54.52500, 0.50, 10.0, 3.1623
54.57500, 0.50, 6.0, 2.4495
54.62500, 0.50, 5.0, 2.2361
54.67500, 0.50, 16.0, 4.0000
54.72500, 0.50, 10.0, 3.1623
54.77500, 0.50, 11.0, 3.3166
54.82500, 0.50, 8.0, 2.8284
54.87500, 0.50, 13.0, 3.6056
54.92500, 0.50, 2.0, 1.4142
54.97500, 0.50, 2.0, 1.4142
55.02500, 0.50, 10.0, 3.1623
55.07500, 0.50, 9.0, 3.0000
55.12500, 0.50, 14.0, 3.7417
55.17500, 0.50, 9.0, 3.0000
55.22500, 0.50, 18.0, 4.2426
55.27500, 0.50, 6.0, 2.4495
55.32500, 0.50, 8.0, 2.8284
55.37500, 0.50, 5.0, 2.2361
55.42500, 0.50, 2.0, 1.4142
55.47500, 0.50, 14.0, 3.7417
55.52500, 0.50, 13.0, 3.6056
55.57500, 0.50, 9.0, 3.0000
55.62500, 0.50, 8.0, 2.8284
55.67500, 0.50, 7.0, 2.6458
55.72500, 0.50, 8.0, 2.8284
55.77500, 0.50, 9.0, 3.0000
55.82500, 0.50, 8.0, 2.8284
55.87500, 0.50, 11.0, 3.3166
55.92500, 0.50, 8.0, 2.8284
55.97500, 0.50, 10.0, 3.1623
56.02500, 0.50, 4.0, 2.0000
56.07500, 0.50, 5.0, 2.2361
56.12500, 0.50, 12.0, 3.4641
56.17500, 0.50, 11.0, 3.3166
56.22500, 0.50, 9.0, 3.0000
56.27500, 0.50, 10.0, 3.1623
56.32500, 0.50, 8.0, 2.8284
56.37500, 0.50, 5.0, 2.2361
56.42500, 0.50, 11.0, 3.3166
56.47500, 0.50, 5.0, 2.2361
56.52500, 0.50, 9.0, 3.0000
56.57500, 0.50, 6.0, 2.4495
56.62500, 0.50, 8.0, 2.8284
56.67500, 0.50, 5.0, 2.2361
56.72500, 0.50, 4.0, 2.0000
56.77500, 0.50, 14.0, 3.7417
56.82500, 0.50, 4.0, 2.0000
56.87500, 0.50, 9.0, 3.0000
56.92500, 0.50, 5.0, 2.2361
56.97500, 0.50, 7.0, 2.6458
57.02500, 0.50, 9.0, 3.0000
57.07500, 0.50, 6.0, 2.4495
57.12500, 0.50, 10.0, 3.1623
57.17500, 0.50, 6.0, 2.4495
57.22500, 0.50, 11.0, 3.3166
57.27500, 0.50, 9.0, 3.0000
57.32500, 0.50, 6.0, 2.4495
57.37500, 0.50, 8.0, 2.8284
57.42500, 0.50, 11.0, 3.3166
57.47500, 0.50, 9.0, 3.0000
57.52500, 0.50, 10.0, 3.1623
57.57500, 0.50, 10.0, 3.1623
57.62500, 0.50, 21.0, 4.5826
57.67500, 0.50, 7.0, 2.6458
57.72500, 0.50, 12.0, 3.4641
57.77500, 0.50, 5.0, 2.2361
57.82500, 0.50, 6.0, 2.4495
57.87500, 0.50, 9.0, 3.0000
57.92500, 0.50, 13.0, 3.6056
57.97500, 0.50, 8.0, 2.8284
58.02500, 0.50, 4.0, 2.0000
58.07500, 0.50, 6.0, 2.4495
58.12500, 0.50, 6.0, 2.4495
58.17500, 0.50, 9.0, 3.0000
58.22500, 0.50, 7.0, 2.6458
58.27500, 0.50, 3.0, 1.7321
58.32500, 0.50, 9.0, 3.0000
58.37500, 0.50, 6.0, 2.4495
58.42500, 0.50, 9.0, 3.0000
58.47500, 0.50, 5.0, 2.2361
58.52500, 0.50, 10.0, 3.1623
58.57500, 0.50, 7.0, 2.6458
58.62500, 0.50, 9.0, 3.0000
58.67500, 0.50, 8.0, 2.8284
58.72500, 0.50, 10.0, 3.1623
58.77500, 0.50, 14.0, 3.7417
58.82500, 0.50, 5.0, 2.2361
58.87500, 0.50, 12.0, 3.4641
58.92500, 0.50, 9.0, 3.0000
58.97500, 0.50, 8.0, 2.8284
59.02500, 0.50, 11.0, 3.3166
59.07500, 0.50, 5.0, 2.2361
59.12500, 0.50, 7.0, 2.6458
59.17500, 0.50, 9.0, 3.0000
59.22500, 0.50, 5.0, 2.2361
59.27500, 0.50, 8.0, 2.8284
59.32500, 0.50, 7.0, 2.6458
59.37500, 0.50, 8.0, 2.8284
59.42500, 0.50, 5.0, 2.2361
59.47500, 0.50, 7.0, 2.6458
59.52500, 0.50, 9.0, 3.0000
59.57500, 0.50, 8.0, 2.8284
59.62500, 0.50, 11.0, 3.3166
59.67500, 0.50, 10.0, 3.1623
59.72500, 0.50, 7.0, 2.6458
59.77500, 0.50, 11.0, 3.3166
59.82500, 0.50, 14.0, 3.7417
59.87500, 0.50, 7.0, 2.6458
59.92500, 0.50, 9.0, 3.0000
59.97500, 0.50, 8.0, 2.8284
60.02500, 0.50, 8.0, 2.8284
60.07500, 0.50, 7.0, 2.6458
60.12500, 0.50, 7.0, 2.6458
60.17500, 0.50, 8.0, 2.8284
60.22500, 0.50, 4.0, 2.0000
60.27500, 0.50, 11.0, 3.3166
60.32500, 0.50, 9.0, 3.0000
60.37500, 0.50, 12.0, 3.4641
60.42500, 0.50, 6.0, 2.4495
60.47500, 0.50, 12.0, 3.4641
60.52500, 0.50, 7.0, 2.6458
60.57500, 0.50, 8.0, 2.8284
60.62500, 0.50, 7.0, 2.6458
60.67500, 0.50, 9.0, 3.0000
60.72500, 0.50, 4.0, 2.0000
60.77500, 0.50, 8.0, 2.8284
60.82500, 0.50, 11.0, 3.3166
60.87500, 0.50, 11.0, 3.3166
60.92500, 0.50, 9.0, 3.0000
60.97500, 0.50, 9.0, 3.0000
61.02500, 0.50, 7.0, 2.6458
61.07500, 0.50, 11.0, 3.3166
61.12500, 0.50, 7.0, 2.6458
61.17500, 0.50, 14.0, 3.7417
61.22500, 0.50, 6.0, 2.4495
61.27500, 0.50, 14.0, 3.7417
61.32500, 0.50, 10.0, 3.1623
61.37500, 0.50, 13.0, 3.6056
61.42500, 0.50, 11.0, 3.3166
61.47500, 0.50, 9.0, 3.0000
61.52500, 0.50, 7.0, 2.6458
61.57500, 0.50, 6.0, 2.4495
61.62500, 0.50, 8.0, 2.8284
61.67500, 0.50, 18.0, 4.2426
61.72500, 0.50, 10.0, 3.1623
61.77500, 0.50, 13.0, 3.6056
61.82500, 0.50, 11.0, 3.3166
61.87500, 0.50, 4.0, 2.0000
61.92500, 0.50, 10.0, 3.1623
61.97500, 0.50, 12.0, 3.4641
62.02500, 0.50, 8.0, 2.8284
62.07500, 0.50, 10.0, 3.1623
62.12500, 0.50, 14.0, 3.7417
62.17500, 0.50, 11.0, 3.3166
62.22500, 0.50, 11.0, 3.3166
62.27500, 0.50, 11.0, 3.3166
62.32500, 0.50, 9.0, 3.0000
62.37500, 0.50, 10.0, 3.1623
62.42500, 0.50, 7.0, 2.6458
62.47500, 0.50, 12.0, 3.4641
62.52500, 0.50, 7.0, 2.6458
62.57500, 0.50, 20.0, 4.4721
62.62500, 0.50, 8.0, 2.8284
62.67500, 0.50, 17.0, 4.1231
62.72500, 0.50, 5.0, 2.2361
62.77500, 0.50, 10.0, 3.1623
62.82500, 0.50, 9.0, 3.0000
62.87500, 0.50, 13.0, 3.6056
62.92500, 0.50, 12.0, 3.4641
62.97500, 0.50, 12.0, 3.4641
63.02500, 0.50, 15.0, 3.8730
63.07500, 0.50, 13.0, 3.6056
63.12500, 0.50, 13.0, 3.6056
63.17500, 0.50, 16.0, 4.0000
63.22500, 0.50, 13.0, 3.6056
63.27500, 0.50, 17.0, 4.1231
63.32500, 0.50, 19.0, 4.3589
63.37500, 0.50, 17.0, 4.1231
63.42500, 0.50, 16.0, 4.0000
63.47500, 0.50, 13.0, 3.6056
63.52500, 0.50, 14.0, 3.7417
63.57500, 0.50, 20.0, 4.4721
63.62500, 0.50, 11.0, 3.3166
63.67500, 0.50, 24.0, 4.8990
63.72500, 0.50, 20.0, 4.4721
63.77500, 0.50, 18.0, 4.2426
63.82500, 0.50, 31.0, 5.5678
63.87500, 0.50, 25.0, 5.0000
63.92500, 0.50, 43.0, 6.5574
63.97500, 0.50, 35.0, 5.9161
64.02500, 0.50, 45.0, 6.7082
64.07500, 0.50, 81.0, 9.0000
64.12500, 0.50, 56.0, 7.4833
64.17500, 0.50, 97.0, 9.8489
64.22500, 0.50, 117.0, 10.8167
64.27500, 0.50, 157.0, 12.5300
64.32500, 0.50, 223.0, 14.9332
64.37500, 0.50, 253.0, 15.9060
64.42500, 0.50, 291.0, 17.0587
64.47500, 0.50, 308.0, 17.5499
64.52500, 0.50, 297.0, 17.2337
64.57500, 0.50, 268.0, 16.3707
64.62500, 0.50, 220.0, 14.8324
64.67500, 0.50, 171.0, 13.0767
64.72500, 0.50, 152.0, 12.3288
64.77500, 0.50, 114.0, 10.6771
64.82500, 0.50, 71.0, 8.4261
64.87500, 0.50, 54.0, 7.3485
64.92500, 0.50, 47.0, 6.8557
64.97500, 0.50, 34.0, 5.8310
65.02500, 0.50, 31.0, 5.5678
65.07500, 0.50, 36.0, 6.0000
65.12500, 0.50, 25.0, 5.0000
65.17500, 0.50, 25.0, 5.0000
65.22500, 0.50, 26.0, 5.0990
65.27500, 0.50, 12.0, 3.4641
65.32500, 0.50, 15.0, 3.8730
65.37500, 0.50, 19.0, 4.3589
65.42500, 0.50, 25.0, 5.0000
65.47500, 0.50, 16.0, 4.0000
65.52500, 0.50, 13.0, 3.6056
65.57500, 0.50, 18.0, 4.2426
65.62500, 0.50, 25.0, 5.0000
65.67500, 0.50, 15.0, 3.8730
65.72500, 0.50, 13.0, 3.6056
65.77500, 0.50, 8.0, 2.8284
65.82500, 0.50, 13.0, 3.6056
65.87500, 0.50, 11.0, 3.3166
65.92500, 0.50, 15.0, 3.8730
65.97500, 0.50, 22.0, 4.6904
66.02500, 0.50, 17.0, 4.1231
66.07500, 0.50, 14.0, 3.7417
66.12500, 0.50, 11.0, 3.3166
66.17500, 0.50, 14.0, 3.7417
66.22500, 0.50, 14.0, 3.7417
66.27500, 0.50, 15.0, 3.8730
66.32500, 0.50, 15.0, 3.8730
66.37500, 0.50, 11.0, 3.3166
66.42500, 0.50, 8.0, 2.8284
66.47500, 0.50, 11.0, 3.3166
66.52500, 0.50, 3.0, 1.7321
66.57500, 0.50, 6.0, 2.4495
66.62500, 0.50, 11.0, 3.3166
66.67500, 0.50, 6.0, 2.4495
66.72500, 0.50, 9.0, 3.0000
66.77500, 0.50, 7.0, 2.6458
66.82500, 0.50, 12.0, 3.4641
66.87500, 0.50, 10.0, 3.1623
66.92500, 0.50, 7.0, 2.6458
66.97500, 0.50, 17.0, 4.1231
67.02500, 0.50, 14.0, 3.7417
67.07500, 0.50, 14.0, 3.7417
67.12500, 0.50, 10.0, 3.1623
67.17500, 0.50, 9.0, 3.0000
67.22500, 0.50, 10.0, 3.1623
67.27500, 0.50, 5.0, 2.2361
67.32500, 0.50, 11.0, 3.3166
67.37500, 0.50, 7.0, 2.6458
67.42500, 0.50, 5.0, 2.2361
67.47500, 0.50, 5.0, 2.2361
67.52500, 0.50, 6.0, 2.4495
67.57500, 0.50, 6.0, 2.4495
67.62500, 0.50, 13.0, 3.6056
67.67500, 0.50, 11.0, 3.3166
67.72500, 0.50, 10.0, 3.1623
67.77500, 0.50, 7.0, 2.6458
67.82500, 0.50, 7.0, 2.6458
67.87500, 0.50, 7.0, 2.6458
67.92500, 0.50, 9.0, 3.0000
67.97500, 0.50, 7.0, 2.6458
68.02500, 0.50, 4.0, 2.0000
68.07500, 0.50, 7.0, 2.6458
68.12500, 0.50, 6.0, 2.4495
68.17500, 0.50, 7.0, 2.6458
68.22500, 0.50, 8.0, 2.8284
68.27500, 0.50, 8.0, 2.8284
68.32500, 0.50, 5.0, 2.2361
68.37500, 0.50, 7.0, 2.6458
68.42500, 0.50, 8.0, 2.8284
68.47500, 0.50, 6.0, 2.4495
68.52500, 0.50, 14.0, 3.7417
68.57500, 0.50, 6.0, 2.4495
68.62500, 0.50, 12.0, 3.4641
68.67500, 0.50, 10.0, 3.1623
68.72500, 0.50, 10.0, 3.1623
68.77500, 0.50, 7.0, 2.6458
68.82500, 0.50, 11.0, 3.3166
68.87500, 0.50, 5.0, 2.2361
68.92500, 0.50, 10.0, 3.1623
68.97500, 0.50, 11.0, 3.3166
69.02500, 0.50, 8.0, 2.8284
69.07500, 0.50, 10.0, 3.1623
69.12500, 0.50, 6.0, 2.4495
69.17500, 0.50, 7.0, 2.6458
69.22500, 0.50, 7.0, 2.6458
69.27500, 0.50, 3.0, 1.7321
69.32500, 0.50, 5.0, 2.2361
69.37500, 0.50, 5.0, 2.2361
69.42500, 0.50, 11.0, 3.3166
69.47500, 0.50, 12.0, 3.4641
69.52500, 0.50, 10.0, 3.1623
69.57500, 0.50, 10.0, 3.1623
69.62500, 0.50, 2.0, 1.4142
69.67500, 0.50, 7.0, 2.6458
69.72500, 0.50, 11.0, 3.3166
69.77500, 0.50, 6.0, 2.4495
69.82500, 0.50, 10.0, 3.1623
69.87500, 0.50, 11.0, 3.3166
69.92500, 0.50, 4.0, 2.0000
69.97500, 0.50, 6.0, 2.4495
70.02500, 0.50, 7.0, 2.6458
70.07500, 0.50, 7.0, 2.6458
70.12500, 0.50, 3.0, 1.7321
70.17500, 0.50, 10.0, 3.1623
70.22500, 0.50, 9.0, 3.0000
70.27500, 0.50, 8.0, 2.8284
70.32500, 0.50, 13.0, 3.6056
70.37500, 0.50, 6.0, 2.4495
70.42500, 0.50, 7.0, 2.6458
70.47500, 0.50, 9.0, 3.0000
70.52500, 0.50, 6.0, 2.4495
70.57500, 0.50, 15.0, 3.8730
70.62500, 0.50, 8.0, 2.8284
70.67500, 0.50, 8.0, 2.8284
70.72500, 0.50, 11.0, 3.3166
70.77500, 0.50, 5.0, 2.2361
70.82500, 0.50, 9.0, 3.0000
70.87500, 0.50, 4.0, 2.0000
70.92500, 0.50, 11.0, 3.3166
70.97500, 0.50, 7.0, 2.6458
71.02500, 0.50, 7.0, 2.6458
71.07500, 0.50, 4.0, 2.0000
71.12500, 0.50, 9.0, 3.0000
71.17500, 0.50, 6.0, 2.4495
71.22500, 0.50, 8.0, 2.8284
71.27500, 0.50, 3.0, 1.7321
71.32500, 0.50, 4.0, 2.0000
71.37500, 0.50, 7.0, 2.6458
71.42500, 0.50, 8.0, 2.8284
71.47500, 0.50, 7.0, 2.6458
71.52500, 0.50, 5.0, 2.2361
71.57500, 0.50, 5.0, 2.2361
71.62500, 0.50, 3.0, 1.7321
71.67500, 0.50, 4.0, 2.0000
71.72500, 0.50, 10.0, 3.1623
71.77500, 0.50, 10.0, 3.1623
71.82500, 0.50, 4.0, 2.0000
71.87500, 0.50, 6.0, 2.4495
71.92500, 0.50, 4.0, 2.0000
71.97500, 0.50, 8.0, 2.8284
72.02500, 0.50, 9.0, 3.0000
72.07500, 0.50, 6.0, 2.4495
72.12500, 0.50, 4.0, 2.0000
72.17500, 0.50, 8.0, 2.8284
72.22500, 0.50, 8.0, 2.8284
72.27500, 0.50, 9.0, 3.0000
72.32500, 0.50, 3.0, 1.7321
72.37500, 0.50, 7.0, 2.6458
72.42500, 0.50, 6.0, 2.4495
72.47500, 0.50, 9.0, 3.0000
72.52500, 0.50, 4.0, 2.0000
72.57500, 0.50, 4.0, 2.0000
72.62500, 0.50, 7.0, 2.6458
72.67500, 0.50, 6.0, 2.4495
72.72500, 0.50, 9.0, 3.0000
72.77500, 0.50, 10.0, 3.1623
72.82500, 0.50, 6.0, 2.4495
72.87500, 0.50, 8.0, 2.8284
72.92500, 0.50, 4.0, 2.0000
72.97500, 0.50, 8.0, 2.8284
73.02500, 0.50, 10.0, 3.1623
73.07500, 0.50, 13.0, 3.6056
73.12500, 0.50, 4.0, 2.0000
73.17500, 0.50, 6.0, 2.4495
73.22500, 0.50, 10.0, 3.1623
73.27500, 0.50, 6.0, 2.4495
73.32500, 0.50, 7.0, 2.6458
73.37500, 0.50, 10.0, 3.1623
73.42500, 0.50, 8.0, 2.8284
73.47500, 0.50, 13.0, 3.6056
73.52500, 0.50, 10.0, 3.1623
73.57500, 0.50, 5.0, 2.2361
73.62500, 0.50, 10.0, 3.1623
73.67500, 0.50, 8.0, 2.8284
73.72500, 0.50, 10.0, 3.1623
73.77500, 0.50, 11.0, 3.3166
73.82500, 0.50, 8.0, 2.8284
73.87500, 0.50, 10.0, 3.1623
73.92500, 0.50, 9.0, 3.0000
73.97500, 0.50, 6.0, 2.4495
74.02500, 0.50, 9.0, 3.0000
74.07500, 0.50, 6.0, 2.4495
74.12500, 0.50, 7.0, 2.6458
74.17500, 0.50, 8.0, 2.8284
74.22500, 0.50, 14.0, 3.7417
74.27500, 0.50, 9.0, 3.0000
74.32500, 0.50, 8.0, 2.8284
74.37500, 0.50, 9.0, 3.0000
74.42500, 0.50, 6.0, 2.4495
74.47500, 0.50, 7.0, 2.6458
74.52500, 0.50, 13.0, 3.6056
74.57500, 0.50, 9.0, 3.0000
74.62500, 0.50, 6.0, 2.4495
74.67500, 0.50, 6.0, 2.4495
74.72500, 0.50, 13.0, 3.6056
74.77500, 0.50, 10.0, 3.1623
74.82500, 0.50, 8.0, 2.8284
74.87500, 0.50, 10.0, 3.1623
74.92500, 0.50, 8.0, 2.8284
74.97500, 0.50, 5.0, 2.2361
75.02500, 0.50, 17.0, 4.1231
75.07500, 0.50, 7.0, 2.6458
75.12500, 0.50, 13.0, 3.6056
75.17500, 0.50, 9.0, 3.0000
75.22500, 0.50, 5.0, 2.2361
75.27500, 0.50, 13.0, 3.6056
75.32500, 0.50, 11.0, 3.3166
75.37500, 0.50, 11.0, 3.3166
75.42500, 0.50, 10.0, 3.1623
75.47500, 0.50, 16.0, 4.0000
75.52500, 0.50, 11.0, 3.3166
75.57500, 0.50, 8.0, 2.8284
75.62500, 0.50, 7.0, 2.6458
75.67500, 0.50, 7.0, 2.6458
75.72500, 0.50, 9.0, 3.0000
75.77500, 0.50, 9.0, 3.0000
75.82500, 0.50, 13.0, 3.6056
75.87500, 0.50, 8.0, 2.8284
75.92500, 0.50, 8.0, 2.8284
75.97500, 0.50, 9.0, 3.0000
76.02500, 0.50, 14.0, 3.7417
76.07500, 0.50, 11.0, 3.3166
76.12500, 0.50, 10.0, 3.1623
76.17500, 0.50, 10.0, 3.1623
76.22500, 0.50, 9.0, 3.0000
76.27500, 0.50, 9.0, 3.0000
76.32500, 0.50, 17.0, 4.1231
76.37500, 0.50, 17.0, 4.1231
76.42500, 0.50, 17.0, 4.1231
76.47500, 0.50, 15.0, 3.8730
76.52500, 0.50, 24.0, 4.8990
76.57500, 0.50, 21.0, 4.5826
76.62500, 0.50, 22.0, 4.6904
76.67500, 0.50, 21.0, 4.5826
76.72500, 0.50, 20.0, 4.4721
76.77500, 0.50, 33.0, 5.7446
76.82500, 0.50, 27.0, 5.1962
76.87500, 0.50, 30.0, 5.4772
76.92500, 0.50, 54.0, 7.3485
76.97500, 0.50, 41.0, 6.4031
77.02500, 0.50, 61.0, 7.8102
77.07500, 0.50, 85.0, 9.2195
77.12500, 0.50, 84.0, 9.1652
77.17500, 0.50, 132.0, 11.4891
77.22500, 0.50, 151.0, 12.2882
77.27500, 0.50, 197.0, 14.0357
77.32500, 0.50, 247.0, 15.7162
77.37500, 0.50, 250.0, 15.8114
77.42500, 0.50, 228.0, 15.0997
77.47500, 0.50, 237.0, 15.3948
77.52500, 0.50, 230.0, 15.1658
77.57500, 0.50, 206.0, 14.3527
77.62500, 0.50, 172.0, 13.1149
77.67500, 0.50, 156.0, 12.4900
77.72500, 0.50, 116.0, 10.7703
77.77500, 0.50, 108.0, 10.3923
77.82500, 0.50, 71.0, 8.4261
77.87500, 0.50, 72.0, 8.4853
77.92500, 0.50, 50.0, 7.0711
77.97500, 0.50, 45.0, 6.7082
78.02500, 0.50, 38.0, 6.1644
78.07500, 0.50, 42.0, 6.4807
78.12500, 0.50, 23.0, 4.7958
78.17500, 0.50, 21.0, 4.5826
78.22500, 0.50, 21.0, 4.5826
78.27500, 0.50, 23.0, 4.7958
78.32500, 0.50, 15.0, 3.8730
78.37500, 0.50, 16.0, 4.0000
78.42500, 0.50, 23.0, 4.7958
78.47500, 0.50, 17.0, 4.1231
78.52500, 0.50, 12.0, 3.4641
78.57500, 0.50, 11.0, 3.3166
78.62500, 0.50, 14.0, 3.7417
78.67500, 0.50, 10.0, 3.1623
78.72500, 0.50, 13.0, 3.6056
78.77500, 0.50, 14.0, 3.7417
78.82500, 0.50, 10.0, 3.1623
78.87500, 0.50, 9.0, 3.0000
78.92500, 0.50, 11.0, 3.3166
78.97500, 0.50, 7.0, 2.6458
79.02500, 0.50, 8.0, 2.8284
79.07500, 0.50, 7.0, 2.6458
79.12500, 0.50, 7.0, 2.6458
79.17500, 0.50, 11.0, 3.3166
79.22500, 0.50, 11.0, 3.3166
79.27500, 0.50, 11.0, 3.3166
79.32500, 0.50, 3.0, 1.7321
79.37500, 0.50, 8.0, 2.8284
79.42500, 0.50, 8.0, 2.8284
79.47500, 0.50, 9.0, 3.0000
79.52500, 0.50, 11.0, 3.3166
79.57500, 0.50, 12.0, 3.4641
79.62500, 0.50, 13.0, 3.6056
79.67500, 0.50, 9.0, 3.0000
79.72500, 0.50, 4.0, 2.0000
79.77500, 0.50, 11.0, 3.3166
79.82500, 0.50, 9.0, 3.0000
79.87500, 0.50, 8.0, 2.8284
79.92500, 0.50, 12.0, 3.4641
79.97500, 0.50, 9.0, 3.0000